Workbook

Sheet RESULT
A1: CONFIDENTIAL — Shared for portfolio review purposes only. All game content is the property of its respective studio.
A2: A. | B2: This bingo table was created with values derived from running the bingo simulator with assistance from the development team.
A3: B. | B3: The Live Server sheet contains data to be delivered to the server development team.
A4: C. | B4: The Control Panel sheet is used by the design team to adjust various expected values.
A5: D. | B5: The Diamond Exchange sheet shows expected values for diamond conversion in the bingo event.
A6: E. | B6: The Simulator sheet is auto-populated with values needed to run the simulator provided by the dev team.
A7: F. | B7: Subsequent sheets are for reference.
A8: G. | B8: Below are aggregated result values.
A11: Daily Expected Value by Bet Range (Based on 3,000 Spins)
A12: 1 | B12: ='Control Panel'!M90
A13: 2 | B13: ='Control Panel'!N90
A14: 3 | B14: ='Control Panel'!O90
A15: 4 | B15: ='Control Panel'!P90
A16: 5 | B16: ='Control Panel'!Q90
G17: =_!O12
A18: Based on 3000 Spins | C18: 13 | D18: Diamondmond | F18: =_!N13 | G18: =_!O13 | H18: =_!P13 | I18: =_!Q13 | J18: =_!R13 | K18: =_!S13
A19: Bingo Level | B19: Avg Bingo Prize | C19: Amount per Symbol | D19: Clear Reward | F19: =_!N14 | G19: =_!O14 | H19: =_!P14 | I19: =_!Q14 | J19: =_!R14 | K19: =_!S14
A20: 1 | B20: 435515.22 | C20: =B19/$C$17 | D20: 20 | F20: =_!N15 | G20: =_!O15 | H20: =_!P15 | I20: =_!Q15 | J20: =_!R15 | K20: =_!S15
A21: 2 | B21: 871030.45 | C21: =B20/$C$17 | D21: 30 | F21: =_!N16 | G21: =_!O16 | H21: =_!P16 | I21: =_!Q16 | J21: =_!R16 | K21: =_!S16
A22: 3 | B22: 1306545.7 | C22: =B21/$C$17 | D22: 40 | F22: =_!N17 | G22: =_!O17 | H22: =_!P17 | I22: =_!Q17 | J22: =_!R17 | K22: =_!S17
A23: 4 | B23: 2177576.1 | C23: =B22/$C$17 | D23: 60 | F23: =_!N18 | G23: =_!O18 | H23: =_!P18 | I23: =_!Q18 | J23: =_!R18 | K23: =_!S18
A24: 5 | B24: 2613091.3 | C24: =B23/$C$17 | D24: 70 | F24: =_!N19 | G24: =_!O19 | H24: =_!P19 | I24: =_!Q19 | J24: =_!R19 | K24: =_!S19
A25: 6 | B25: 3048606.6 | C25: =B24/$C$17 | D25: 100 | F25: =_!N20 | G25: =_!O20 | H25: =_!P20 | I25: =_!Q20 | J25: =_!R20 | K25: =_!S20
A26: 7 | B26: 3484121.8 | C26: =B25/$C$17 | D26: 150 | F26: =_!N21 | G26: =_!O21 | H26: =_!P21 | I26: =_!Q21 | J26: =_!R21 | K26: =_!S21
A27: 8 | B27: 4355152.2 | C27: =B26/$C$17 | D27: 200 | F27: =_!N22 | G27: =_!O22 | H27: =_!P22 | I27: =_!Q22 | J27: =_!R22 | K27: =_!S22
F28: =_!G19 | G28: =_!H19 | H28: =_!I19 | I28: =_!J19 | J28: =_!K19 | K28: =_!L19 | L28: Base Coin
G29: =_!H20 | H29: =_!I20 | I29: =_!J20 | J29: =_!K20 | K29: =_!L20 | L29: Bingo Coin Expected Value
G30: =_!H21 | H30: =_!I21 | I30: =_!J21 | J30: =_!K21 | K30: =_!L21 | L30: Total
G31: =_!H22 | H31: =_!I22 | I31: =_!J22 | J31: =_!K22 | K31: =_!L22
F32: =_!G23 | G32: =_!H23
A34: Added to Prize Window Diamond Composition | L34: Bingo Position Expected Value
A35: Prize | B35: Count | C35: Expected Value | D35: C1 | E35: C2 | F35: C3 | G35: C4 | H35: C5 | I35: C6 | J35: C7 | L35: =_!N2 | M35: =_!O2 | N35: =_!P2 | O35: =_!Q2 | P35: =_!R2 | Q35: =_!S2 | R35: Multi | T35: ='Control Panel'!M9 | U35: ='Control Panel'!N9 | V35: ='Control Panel'!O9 | W35: ='Control Panel'!P9 | X35: ='Control Panel'!Q9 | Y35: ='Control Panel'!R9 | Z35: ='Control Panel'!S9 | AA35: ='Control Panel'!T9 | AB35: ='Control Panel'!U9
A36: Unreleased | B36: Unreleased | C36: Unreleased | D36: Unreleased | E36: Unreleased | F36: Unreleased | G36: Unreleased | H36: Unreleased | I36: Unreleased | J36: Unreleased | L36: =_!N3 | M36: ='Control Panel'!AA19 | N36: ='Control Panel'!AA34 | O36: ='Control Panel'!AA49 | P36: ='Control Panel'!AA64 | Q36: ='Control Panel'!AA79 | R36: ='Control Panel'!V10 | T36: ='Control Panel'!M10 | U36: ='Control Panel'!N10 | V36: ='Control Panel'!O10 | W36: ='Control Panel'!P10 | X36: ='Control Panel'!Q10 | Y36: ='Control Panel'!R10 | Z36: ='Control Panel'!S10 | AA36: ='Control Panel'!T10 | AB36: ='Control Panel'!U10
A37: Unreleased | B37: Unreleased | C37: Unreleased | D37: Unreleased | E37: Unreleased | F37: Unreleased | G37: Unreleased | H37: Unreleased | I37: Unreleased | J37: Unreleased | L37: =_!N4 | M37: ='Control Panel'!AG19 | N37: ='Control Panel'!AG34 | O37: ='Control Panel'!AG49 | P37: ='Control Panel'!AG64 | Q37: ='Control Panel'!AG79 | R37: ='Control Panel'!V11 | T37: ='Control Panel'!M11 | U37: ='Control Panel'!N11 | V37: ='Control Panel'!O11 | W37: ='Control Panel'!P11 | X37: ='Control Panel'!Q11 | Y37: ='Control Panel'!R11 | Z37: ='Control Panel'!S11 | AA37: ='Control Panel'!T11 | AB37: ='Control Panel'!U11
A38: Unreleased | B38: Unreleased | C38: Unreleased | D38: Unreleased | E38: Unreleased | F38: Unreleased | G38: Unreleased | H38: Unreleased | I38: Unreleased | J38: Unreleased | L38: =_!N5 | M38: ='Control Panel'!AM19 | N38: ='Control Panel'!AM34 | O38: ='Control Panel'!AM49 | P38: ='Control Panel'!AM64 | Q38: ='Control Panel'!AM79 | R38: ='Control Panel'!V12 | T38: ='Control Panel'!M12 | U38: ='Control Panel'!N12 | V38: ='Control Panel'!O12 | W38: ='Control Panel'!P12 | X38: ='Control Panel'!Q12 | Y38: ='Control Panel'!R12 | Z38: ='Control Panel'!S12 | AA38: ='Control Panel'!T12 | AB38: ='Control Panel'!U12
A39: Unreleased | B39: Unreleased | C39: Unreleased | D39: Unreleased | E39: Unreleased | F39: Unreleased | G39: Unreleased | H39: Unreleased | I39: Unreleased | J39: Unreleased | L39: =_!N6 | M39: ='Control Panel'!AS19 | N39: ='Control Panel'!AS34 | O39: ='Control Panel'!AS49 | P39: ='Control Panel'!AS64 | Q39: ='Control Panel'!AS79 | R39: ='Control Panel'!V13 | T39: ='Control Panel'!M13 | U39: ='Control Panel'!N13 | V39: ='Control Panel'!O13 | W39: ='Control Panel'!P13 | X39: ='Control Panel'!Q13 | Y39: ='Control Panel'!R13 | Z39: ='Control Panel'!S13 | AA39: ='Control Panel'!T13 | AB39: ='Control Panel'!U13
A40: Unreleased | B40: Unreleased | C40: Unreleased | D40: Unreleased | E40: Unreleased | F40: Unreleased | G40: Unreleased | H40: Unreleased | I40: Unreleased | J40: Unreleased | L40: =_!N7 | M40: ='Control Panel'!AA26 | N40: ='Control Panel'!AA41 | O40: ='Control Panel'!AA56 | P40: ='Control Panel'!AA71 | Q40: ='Control Panel'!AA86 | R40: ='Control Panel'!V14 | T40: ='Control Panel'!M14 | U40: ='Control Panel'!N14 | V40: ='Control Panel'!O14 | W40: ='Control Panel'!P14 | X40: ='Control Panel'!Q14 | Y40: ='Control Panel'!R14 | Z40: ='Control Panel'!S14 | AA40: ='Control Panel'!T14 | AB40: ='Control Panel'!U14
A41: Unreleased | B41: Unreleased | C41: Unreleased | D41: Unreleased | E41: Unreleased | F41: Unreleased | G41: Unreleased | H41: Unreleased | I41: Unreleased | J41: Unreleased | L41: =_!N8 | M41: ='Control Panel'!AG26 | N41: ='Control Panel'!AG41 | O41: ='Control Panel'!AG56 | P41: ='Control Panel'!AG71 | Q41: ='Control Panel'!AG86 | R41: ='Control Panel'!V15 | T41: ='Control Panel'!M15 | U41: ='Control Panel'!N15 | V41: ='Control Panel'!O15 | W41: ='Control Panel'!P15 | X41: ='Control Panel'!Q15 | Y41: ='Control Panel'!R15 | Z41: ='Control Panel'!S15 | AA41: ='Control Panel'!T15 | AB41: ='Control Panel'!U15
A42: Unreleased | B42: Unreleased | C42: Unreleased | D42: Unreleased | E42: Unreleased | F42: Unreleased | G42: Unreleased | H42: Unreleased | I42: Unreleased | J42: Unreleased | L42: =_!N9 | M42: ='Control Panel'!AM26 | N42: ='Control Panel'!AM41 | O42: ='Control Panel'!AM56 | P42: ='Control Panel'!AM71 | Q42: ='Control Panel'!AM86 | R42: ='Control Panel'!V16 | T42: ='Control Panel'!M16 | U42: ='Control Panel'!N16 | V42: ='Control Panel'!O16 | W42: ='Control Panel'!P16 | X42: ='Control Panel'!Q16 | Y42: ='Control Panel'!R16 | Z42: ='Control Panel'!S16 | AA42: ='Control Panel'!T16 | AB42: ='Control Panel'!U16
A43: Unreleased | B43: Unreleased | C43: Unreleased | D43: Unreleased | E43: Unreleased | F43: Unreleased | G43: Unreleased | H43: Unreleased | I43: Unreleased | J43: Unreleased | L43: =_!N10 | M43: ='Control Panel'!AS26 | N43: ='Control Panel'!AS41 | O43: ='Control Panel'!AS56 | P43: ='Control Panel'!AS71 | Q43: ='Control Panel'!AS86 | R43: ='Control Panel'!V17 | T43: ='Control Panel'!M17 | U43: ='Control Panel'!N17 | V43: ='Control Panel'!O17 | W43: ='Control Panel'!P17 | X43: ='Control Panel'!Q17 | Y43: ='Control Panel'!R17 | Z43: ='Control Panel'!S17 | AA43: ='Control Panel'!T17 | AB43: ='Control Panel'!U17
...

Sheet Control Panel
A1: CONFIDENTIAL — Shared for portfolio review purposes only. All game content is the property of its respective studio.
B2: Collect | C2: 50 | D2: Miss | E2: =1000-C1 | F2: <- Appearance Probability Setting | I2: =E1/C1 | L2: Bingo Reward Probability Table | AA2: B5 | AB2: <-- | AC2: B1 | AD2: B2 | AE2: B3 | AF2: B4 | AG2: B5 | AH2: <- Bet Range Input
L3: 1 | M3: 2 | N3: 3 | O3: 4 | P3: 5 | Q3: 6 | R3: 7 | S3: 8 | T3: 9
B4: Multi | D4: 1.25 | E4: 1.5 | F4: 2 | G4: 2.5 | H4: 3 | I4: 4 | L4: Gem | M4: Grand | N4: Mega | O4: Major | P4: Minor | Q4: Mini | R4: Coin1 | S4: Coin2 | T4: Coin3 | Z4: =SUM(AA4:AE8,AG4:AK8,AM4:AQ8,AS4:AW8,AA11:AE15,AG11:AK15,AM11:AQ15,AS11:AW15)-SUM(AC6,AI6,AO6,AU6,AC13,AI13,AO13,AU13) | AA4: =AA18 | AG4: Level2 | AM4: Level3 | AS4: Level4
B5: Class | C5: 1 | D5: 2 | E5: 3 | F5: 4 | G5: 5 | H5: 6 | I5: 7 | J5: Average | L5: 0 | M5: 5 | N5: =Q20 | O5: =Q21 | P5: =Q22 | Q5: =Q23 | R5: =Q24 | S5: =Q25 | T5: 1732 | U5: =SUM(L4:T4) | V5: <-Bingo Coin Appearance Probability Setting | AA5: =ROUND(IF($AA$1="B1", AA19, IF($AA$1="B2", AA34, IF($AA$1="B3", AA49, IF($AA$1="B4", AA64, IF($AA$1="B5", AA79, ""))))), 0) | AB5: =AA4 | AC5: =AB4 | AD5: =AC4 | AE5: =AD4 | AG5: =ROUND(IF($AA$1="B1", AG19, IF($AA$1="B2", AG34, IF($AA$1="B3", AG49, IF($AA$1="B4", AG64, IF($AA$1="B5", AG79, ""))))), 0) | AH5: =AG4 | AI5: =AH4 | AJ5: =AI4 | AK5: =AJ4 | AM5: =ROUND(IF($AA$1="B1", AM19, IF($AA$1="B2", AM34, IF($AA$1="B3", AM49, IF($AA$1="B4", AM64, IF($AA$1="B5", AM79, ""))))), 0) | AN5: =AM4 | AO5: =AN4 | AP5: =AO4 | AQ5: =AP4 | AS5: =ROUND(IF($AA$1="B1", AS19, IF($AA$1="B2", AS34, IF($AA$1="B3", AS49, IF($AA$1="B4", AS64, IF($AA$1="B5", AS79, ""))))), 0) | AT5: =AS4 | AU5: =AT4 | AV5: =AU4 | AW5: =AV4 | DG5: =ROUNDDOWN(#REF!,0) | DH5: =ROUNDDOWN(#REF!,0) | DI5: =ROUNDDOWN(#REF!,0) | DJ5: =ROUNDDOWN(#REF!,0) | DK5: =ROUNDDOWN(#REF!,0) | DM5: =ROUNDDOWN(#REF!,0) | DN5: =ROUNDDOWN(#REF!,0) | DO5: =ROUNDDOWN(#REF!,0) | DP5: =ROUNDDOWN(#REF!,0) | DQ5: =ROUNDDOWN(#REF!,0) | DS5: =ROUNDDOWN(#REF!,0) | DT5: =ROUNDDOWN(#REF!,0) | DU5: =ROUNDDOWN(#REF!,0) | DV5: =ROUNDDOWN(#REF!,0) | DW5: =ROUNDDOWN(#REF!,0) | DY5: =ROUNDDOWN(#REF!,0) | DZ5: =ROUNDDOWN(#REF!,0) | EA5: =ROUNDDOWN(#REF!,0) | EB5: =ROUNDDOWN(#REF!,0) | EC5: =ROUNDDOWN(#REF!,0)
B6: Avg Bet | C6: =BACK!F3 | D6: =BACK!F4 | E6: =BACK!F5 | F6: =BACK!F6 | G6: =BACK!F7 | H6: =BACK!F8 | I6: =BACK!F9 | J6: =AVERAGE(C5:I5) | L6: Expected Value | M6: =AVERAGE(N10:N17)*M4/10000 | N6: =AVERAGE(O10:O17)*N4/10000 | O6: =AVERAGE(P10:P17)*O4/10000 | P6: =AVERAGE(Q10:Q17)*P4/10000 | Q6: =AVERAGE(R10:R17)*Q4/10000 | R6: =AVERAGE(S10:S17)*R4/10000 | S6: =AVERAGE(T10:T17)*S4/10000 | T6: =AVERAGE(U10:U17)*T4/10000 | AA6: =AA4 | AB6: =AA5 | AC6: =AB5 | AD6: =AC5 | AE6: =AD5 | AG6: =AG4 | AH6: =AG5 | AI6: =AH5 | AJ6: =AI5 | AK6: =AJ5 | AM6: =AM4 | AN6: =AM5 | AO6: =AN5 | AP6: =AO5 | AQ6: =AP5 | AS6: =AS4 | AT6: =AS5 | AU6: =AT5 | AV6: =AU5 | AW6: =AV5 | DG6: =ROUNDDOWN(#REF!,0) | DH6: =ROUNDDOWN(#REF!,0) | DI6: =ROUNDDOWN(#REF!,0) | DJ6: =ROUNDDOWN(#REF!,0) | DK6: =ROUNDDOWN(#REF!,0) | DM6: =ROUNDDOWN(#REF!,0) | DN6: =ROUNDDOWN(#REF!,0) | DO6: =ROUNDDOWN(#REF!,0) | DP6: =ROUNDDOWN(#REF!,0) | DQ6: =ROUNDDOWN(#REF!,0) | DS6: =ROUNDDOWN(#REF!,0) | DT6: =ROUNDDOWN(#REF!,0) | DU6: =ROUNDDOWN(#REF!,0) | DV6: =ROUNDDOWN(#REF!,0) | DW6: =ROUNDDOWN(#REF!,0) | DY6: =ROUNDDOWN(#REF!,0) | DZ6: =ROUNDDOWN(#REF!,0) | EA6: =ROUNDDOWN(#REF!,0) | EB6: =ROUNDDOWN(#REF!,0) | EC6: =ROUNDDOWN(#REF!,0)
B7: Avg Spins | C7: =BACK!D3 | D7: =BACK!D4 | E7: =BACK!D5 | F7: =BACK!D6 | G7: =BACK!D7 | H7: =BACK!D8 | I7: =BACK!D9 | J7: 305 | AA7: =AA5 | AB7: =AA6 | AC7: =AB6 | AD7: =AC6 | AE7: =AD6 | AG7: =AG5 | AH7: =AG6 | AI7: =AH6 | AJ7: =AI6 | AK7: =AJ6 | AM7: =AM5 | AN7: =AM6 | AO7: =AN6 | AP7: =AO6 | AQ7: =AP6 | AS7: =AS5 | AT7: =AS6 | AU7: =AT6 | AV7: =AU6 | AW7: =AV6 | DG7: =ROUNDDOWN(#REF!,0) | DH7: =ROUNDDOWN(#REF!,0) | DJ7: =ROUNDDOWN(#REF!,0) | DK7: =ROUNDDOWN(#REF!,0) | DM7: =ROUNDDOWN(#REF!,0) | DN7: =ROUNDDOWN(#REF!,0) | DP7: =ROUNDDOWN(#REF!,0) | DQ7: =ROUNDDOWN(#REF!,0) | DS7: =ROUNDDOWN(#REF!,0) | DT7: =ROUNDDOWN(#REF!,0) | DV7: =ROUNDDOWN(#REF!,0) | DW7: =ROUNDDOWN(#REF!,0) | DY7: =ROUNDDOWN(#REF!,0) | DZ7: =ROUNDDOWN(#REF!,0) | EB7: =ROUNDDOWN(#REF!,0) | EC7: =ROUNDDOWN(#REF!,0)
B8: Attendance Rate | C8: =BACK!L3 | D8: =BACK!L4 | E8: =BACK!L5 | F8: =BACK!L6 | G8: =BACK!L7 | H8: =BACK!L8 | I8: =BACK!L9 | J8: =AVERAGE(C7:I7) | M8: Bingo Reward Amount Table | AA8: =AA6 | AB8: =AA7 | AC8: =AB7 | AD8: =AC7 | AE8: =AD7 | AG8: =AG6 | AH8: =AG7 | AI8: =AH7 | AJ8: =AI7 | AK8: =AJ7 | AM8: =AM6 | AN8: =AM7 | AO8: =AN7 | AP8: =AO7 | AQ8: =AP7 | AS8: =AS6 | AT8: =AS7 | AU8: =AT7 | AV8: =AU7 | AW8: =AV7 | DG8: =ROUNDDOWN(#REF!,0) | DH8: =ROUNDDOWN(#REF!,0) | DI8: =ROUNDDOWN(#REF!,0) | DJ8: =ROUNDDOWN(#REF!,0) | DK8: =ROUNDDOWN(#REF!,0) | DM8: =ROUNDDOWN(#REF!,0) | DN8: =ROUNDDOWN(#REF!,0) | DO8: =ROUNDDOWN(#REF!,0) | DP8: =ROUNDDOWN(#REF!,0) | DQ8: =ROUNDDOWN(#REF!,0) | DS8: =ROUNDDOWN(#REF!,0) | DT8: =ROUNDDOWN(#REF!,0) | DU8: =ROUNDDOWN(#REF!,0) | DV8: =ROUNDDOWN(#REF!,0) | DW8: =ROUNDDOWN(#REF!,0) | DY8: =ROUNDDOWN(#REF!,0) | DZ8: =ROUNDDOWN(#REF!,0) | EA8: =ROUNDDOWN(#REF!,0) | EB8: =ROUNDDOWN(#REF!,0) | EC8: =ROUNDDOWN(#REF!,0)
B9: Population Ratio | C9: 0.10023293 | D9: 0.23502893 | E9: 0.30858817 | F9: 0.2179728 | G9: 0.099932377 | H9: 0.025471485 | I9: 0.012773311 | M9: 1 | N9: 2 | O9: 3 | P9: 4 | Q9: 5 | R9: 6 | S9: 7 | T9: 8 | U9: 9 | AA9: =AA7 | AB9: =AA8 | AC9: =AB8 | AD9: =AC8 | AE9: =AD8 | AG9: =AG7 | AH9: =AG8 | AI9: =AH8 | AJ9: =AI8 | AK9: =AJ8 | AM9: =AM7 | AN9: =AM8 | AO9: =AN8 | AP9: =AO8 | AQ9: =AP8 | AS9: =AS7 | AT9: =AS8 | AU9: =AT8 | AV9: =AU8 | AW9: =AV8 | DG9: =ROUNDDOWN(#REF!,0) | DH9: =ROUNDDOWN(#REF!,0) | DI9: =ROUNDDOWN(#REF!,0) | DJ9: =ROUNDDOWN(#REF!,0) | DK9: =ROUNDDOWN(#REF!,0) | DM9: =ROUNDDOWN(#REF!,0) | DN9: =ROUNDDOWN(#REF!,0) | DO9: =ROUNDDOWN(#REF!,0) | DP9: =ROUNDDOWN(#REF!,0) | DQ9: =ROUNDDOWN(#REF!,0) | DS9: =ROUNDDOWN(#REF!,0) | DT9: =ROUNDDOWN(#REF!,0) | DU9: =ROUNDDOWN(#REF!,0) | DV9: =ROUNDDOWN(#REF!,0) | DW9: =ROUNDDOWN(#REF!,0) | DY9: =ROUNDDOWN(#REF!,0) | DZ9: =ROUNDDOWN(#REF!,0) | EA9: =ROUNDDOWN(#REF!,0) | EB9: =ROUNDDOWN(#REF!,0) | EC9: =ROUNDDOWN(#REF!,0)
A10: No. | B10: Total Bet | C10: BET Range | D10: BET Range | E10: BET Range | F10: BET Range | G10: BET Range | H10: BET Range | I10: BET Range | L10: Level | M10: Default Center Diamond | N10: Grand | O10: Mega | P10: Major | Q10: Minor | R10: Mini | S10: Coin1 | T10: Coin2 | U10: Coin3 | V10: Multi | W10: =#REF! | X10: Expected Value | Y10: Bingo Win Expected Value | DJ10: =SUM(DG11:DK15) | DP10: =SUM(DM11:DQ15) | DV10: =SUM(DS11:DW15) | EB10: =SUM(DY11:EC15)
A11: 1 | B11: 10000 Under | C11: 0 | D11: 0 | E11: 0 | F11: 0 | G11: 0 | H11: 0 | I11: 0 | L11: 1 | M11: 200000 | N11: 100000000 | O11: 3000000 | P11: 1000000 | Q11: 300000 | R11: 100000 | S11: 30000 | T11: 50000 | U11: 70000 | V11: 1 | W11: =$W$9/V10 | X11: =SUM($M10/3,($N10*$M$4)/1000,($O10*$N$4)/1000,($P10*$O$4)/1000,($Q10*$P$4)/1000,($R10*$Q$4)/1000,($S10*$R$4)/1000,($T10*$S$4)/1000,($U10*$T$4)/1000) | Y11: =X10*5 | Z11: <- Reward Value Setting | AA11: =AA25 | AG11: Level6 | AM11: Level7 | AS11: Level8 | DG11: Level5 | DM11: Level6 | DS11: Level7 | DY11: Level8
A12: 2 | B12: 10000 | C12: 1 | D12: 0 | E12: 0 | F12: 0 | G12: 0 | H12: 0 | I12: 0 | L12: 2 | M12: =M$10*V11 | N12: 100000000 | O12: =(O$10*$V11) | P12: =(P$10*$V11) | Q12: =(Q$10*$V11) | R12: =(R$10*$V11) | S12: =(S$10*$V11) | T12: =(T$10*$V11) | U12: =(U$10*$V11) | V12: 2 | W12: =$W$9/V11 | X12: =SUM($M11/3,($N11*$M$4)/1000,($O11*$N$4)/1000,($P11*$O$4)/1000,($Q11*$P$4)/1000,($R11*$Q$4)/1000,($S11*$R$4)/1000,($T11*$S$4)/1000,($U11*$T$4)/1000) | Y12: =X11*5 | AA12: =ROUND(IF($AA$1="B1", AA26, IF($AA$1="B2", AA41, IF($AA$1="B3", AA56, IF($AA$1="B4", AA71, IF($AA$1="B5", AA86, ""))))), 0) | AB12: =AA11 | AC12: =AB11 | AD12: =AC11 | AE12: =AD11 | AG12: =ROUND(IF($AA$1="B1", AG26, IF($AA$1="B2", AG41, IF($AA$1="B3", AG56, IF($AA$1="B4", AG71, IF($AA$1="B5", AG86, ""))))), 0) | AH12: =AG11 | AI12: =AH11 | AJ12: =AI11 | AK12: =AJ11 | AM12: =ROUND(IF($AA$1="B1", AM26, IF($AA$1="B2", AM41, IF($AA$1="B3", AM56, IF($AA$1="B4", AM71, IF($AA$1="B5", AM86, ""))))), 0) | AN12: =AM11 | AO12: =AN11 | AP12: =AO11 | AQ12: =AP11 | AS12: =ROUND(IF($AA$1="B1", AS26, IF($AA$1="B2", AS41, IF($AA$1="B3", AS56, IF($AA$1="B4", AS71, IF($AA$1="B5", AS86, ""))))), 0) | AT12: =AS11 | AU12: =AT11 | AV12: =AU11 | AW12: =AV11 | DG12: =ROUNDDOWN(#REF!,0) | DH12: =ROUNDDOWN(#REF!,0) | DI12: =ROUNDDOWN(#REF!,0) | DJ12: =ROUNDDOWN(#REF!,0) | DK12: =ROUNDDOWN(#REF!,0) | DM12: =ROUNDDOWN(#REF!,0) | DN12: =ROUNDDOWN(#REF!,0) | DO12: =ROUNDDOWN(#REF!,0) | DP12: =ROUNDDOWN(#REF!,0) | DQ12: =ROUNDDOWN(#REF!,0) | DS12: =ROUNDDOWN(#REF!,0) | DT12: =ROUNDDOWN(#REF!,0) | DU12: =ROUNDDOWN(#REF!,0) | DV12: =ROUNDDOWN(#REF!,0) | DW12: =ROUNDDOWN(#REF!,0) | DY12: =ROUNDDOWN(#REF!,0) | DZ12: =ROUNDDOWN(#REF!,0) | EA12: =ROUNDDOWN(#REF!,0) | EB12: =ROUNDDOWN(#REF!,0) | EC12: =ROUNDDOWN(#REF!,0)
A13: 3 | B13: 50000 | C13: 1 | D13: 1 | E13: 0 | F13: 0 | G13: 0 | H13: 0 | I13: 0 | L13: 3 | M13: =M$10*V12 | N13: 100000000 | O13: =(O$10*$V12) | P13: =(P$10*$V12) | Q13: =(Q$10*$V12) | R13: =(R$10*$V12) | S13: =(S$10*$V12) | T13: =(T$10*$V12) | U13: =(U$10*$V12) | V13: 3 | W13: =$W$9/V12 | X13: =SUM($M12/3,($N12*$M$4)/1000,($O12*$N$4)/1000,($P12*$O$4)/1000,($Q12*$P$4)/1000,($R12*$Q$4)/1000,($S12*$R$4)/1000,($T12*$S$4)/1000,($U12*$T$4)/1000) | Y13: =X12*5 | AA13: =AA11 | AB13: =AA12 | AC13: =AB12 | AD13: =AC12 | AE13: =AD12 | AG13: =AG11 | AH13: =AG12 | AI13: =AH12 | AJ13: =AI12 | AK13: =AJ12 | AM13: =AM11 | AN13: =AM12 | AO13: =AN12 | AP13: =AO12 | AQ13: =AP12 | AS13: =AS11 | AT13: =AS12 | AU13: =AT12 | AV13: =AU12 | AW13: =AV12 | DG13: =ROUNDDOWN(#REF!,0) | DH13: =ROUNDDOWN(#REF!,0) | DI13: =ROUNDDOWN(#REF!,0) | DJ13: =ROUNDDOWN(#REF!,0) | DK13: =ROUNDDOWN(#REF!,0) | DM13: =ROUNDDOWN(#REF!,0) | DN13: =ROUNDDOWN(#REF!,0) | DO13: =ROUNDDOWN(#REF!,0) | DP13: =ROUNDDOWN(#REF!,0) | DQ13: =ROUNDDOWN(#REF!,0) | DS13: =ROUNDDOWN(#REF!,0) | DT13: =ROUNDDOWN(#REF!,0) | DU13: =ROUNDDOWN(#REF!,0) | DV13: =ROUNDDOWN(#REF!,0) | DW13: =ROUNDDOWN(#REF!,0) | DY13: =ROUNDDOWN(#REF!,0) | DZ13: =ROUNDDOWN(#REF!,0) | EA13: =ROUNDDOWN(#REF!,0) | EB13: =ROUNDDOWN(#REF!,0) | EC13: =ROUNDDOWN(#REF!,0)
A14: 4 | B14: 100000 | C14: 2 | D14: 1 | E14: 1 | F14: 1 | G14: 1 | H14: 0 | I14: 0 | L14: 4 | M14: =M$10*V13 | N14: 100000000 | O14: =(O$10*$V13) | P14: =(P$10*$V13) | Q14: =(Q$10*$V13) | R14: =(R$10*$V13) | S14: =(S$10*$V13) | T14: =(T$10*$V13) | U14: =(U$10*$V13) | V14: 5 | W14: =$W$9/V13 | X14: =SUM($M13/3,($N13*$M$4)/1000,($O13*$N$4)/1000,($P13*$O$4)/1000,($Q13*$P$4)/1000,($R13*$Q$4)/1000,($S13*$R$4)/1000,($T13*$S$4)/1000,($U13*$T$4)/1000) | Y14: =X13*5 | AA14: =AA12 | AB14: =AA13 | AC14: =AB13 | AD14: =AC13 | AE14: =AD13 | AG14: =AG12 | AH14: =AG13 | AI14: =AH13 | AJ14: =AI13 | AK14: =AJ13 | AM14: =AM12 | AN14: =AM13 | AO14: =AN13 | AP14: =AO13 | AQ14: =AP13 | AS14: =AS12 | AT14: =AS13 | AU14: =AT13 | AV14: =AU13 | AW14: =AV13 | DG14: =ROUNDDOWN(#REF!,0) | DH14: =ROUNDDOWN(#REF!,0) | DJ14: =ROUNDDOWN(#REF!,0) | DK14: =ROUNDDOWN(#REF!,0) | DM14: =ROUNDDOWN(#REF!,0) | DN14: =ROUNDDOWN(#REF!,0) | DP14: =ROUNDDOWN(#REF!,0) | DQ14: =ROUNDDOWN(#REF!,0) | DS14: =ROUNDDOWN(#REF!,0) | DT14: =ROUNDDOWN(#REF!,0) | DV14: =ROUNDDOWN(#REF!,0) | DW14: =ROUNDDOWN(#REF!,0) | DY14: =ROUNDDOWN(#REF!,0) | DZ14: =ROUNDDOWN(#REF!,0) | EB14: =ROUNDDOWN(#REF!,0) | EC14: =ROUNDDOWN(#REF!,0)
A15: 5 | B15: 200000 | C15: 2 | D15: 1 | E15: 1 | F15: 1 | G15: 1 | H15: 1 | I15: 0 | L15: 5 | M15: =M$10*V14 | N15: 100000000 | O15: =(O$10*$V14) | P15: =(P$10*$V14) | Q15: =(Q$10*$V14) | R15: =(R$10*$V14) | S15: =(S$10*$V14) | T15: =(T$10*$V14) | U15: =(U$10*$V14) | V15: 6 | W15: =$W$9/V14 | X15: =SUM($M14/3,($N14*$M$4)/1000,($O14*$N$4)/1000,($P14*$O$4)/1000,($Q14*$P$4)/1000,($R14*$Q$4)/1000,($S14*$R$4)/1000,($T14*$S$4)/1000,($U14*$T$4)/1000) | Y15: =X14*5 | AA15: =AA13 | AB15: =AA14 | AC15: =AB14 | AD15: =AC14 | AE15: =AD14 | AG15: =AG13 | AH15: =AG14 | AI15: =AH14 | AJ15: =AI14 | AK15: =AJ14 | AM15: =AM13 | AN15: =AM14 | AO15: =AN14 | AP15: =AO14 | AQ15: =AP14 | AS15: =AS13 | AT15: =AS14 | AU15: =AT14 | AV15: =AU14 | AW15: =AV14 | DG15: =ROUNDDOWN(#REF!,0) | DH15: =ROUNDDOWN(#REF!,0) | DI15: =ROUNDDOWN(#REF!,0) | DJ15: =ROUNDDOWN(#REF!,0) | DK15: =ROUNDDOWN(#REF!,0) | DM15: =ROUNDDOWN(#REF!,0) | DN15: =ROUNDDOWN(#REF!,0) | DO15: =ROUNDDOWN(#REF!,0) | DP15: =ROUNDDOWN(#REF!,0) | DQ15: =ROUNDDOWN(#REF!,0) | DS15: =ROUNDDOWN(#REF!,0) | DT15: =ROUNDDOWN(#REF!,0) | DU15: =ROUNDDOWN(#REF!,0) | DV15: =ROUNDDOWN(#REF!,0) | DW15: =ROUNDDOWN(#REF!,0) | DY15: =ROUNDDOWN(#REF!,0) | DZ15: =ROUNDDOWN(#REF!,0) | EA15: =ROUNDDOWN(#REF!,0) | EB15: =ROUNDDOWN(#REF!,0) | EC15: =ROUNDDOWN(#REF!,0)
A16: 6 | B16: 300000 | C16: 3 | D16: 2 | E16: 1 | F16: 1 | G16: 1 | H16: 1 | I16: 1 | L16: 6 | M16: =M$10*V15 | N16: 100000000 | O16: =(O$10*$V15) | P16: =(P$10*$V15) | Q16: =(Q$10*$V15) | R16: =(R$10*$V15) | S16: =(S$10*$V15) | T16: =(T$10*$V15) | U16: =(U$10*$V15) | V16: 7 | W16: =$W$9/V15 | X16: =SUM($M15/3,($N15*$M$4)/1000,($O15*$N$4)/1000,($P15*$O$4)/1000,($Q15*$P$4)/1000,($R15*$Q$4)/1000,($S15*$R$4)/1000,($T15*$S$4)/1000,($U15*$T$4)/1000) | Y16: =X15*5 | AA16: =AA14 | AB16: =AA15 | AC16: =AB15 | AD16: =AC15 | AE16: =AD15 | AG16: =AG14 | AH16: =AG15 | AI16: =AH15 | AJ16: =AI15 | AK16: =AJ15 | AM16: =AM14 | AN16: =AM15 | AO16: =AN15 | AP16: =AO15 | AQ16: =AP15 | AS16: =AS14 | AT16: =AS15 | AU16: =AT15 | AV16: =AU15 | AW16: =AV15 | DG16: =ROUNDDOWN(#REF!,0) | DH16: =ROUNDDOWN(#REF!,0) | DI16: =ROUNDDOWN(#REF!,0) | DJ16: =ROUNDDOWN(#REF!,0) | DK16: =ROUNDDOWN(#REF!,0) | DM16: =ROUNDDOWN(#REF!,0) | DN16: =ROUNDDOWN(#REF!,0) | DO16: =ROUNDDOWN(#REF!,0) | DP16: =ROUNDDOWN(#REF!,0) | DQ16: =ROUNDDOWN(#REF!,0) | DS16: =ROUNDDOWN(#REF!,0) | DT16: =ROUNDDOWN(#REF!,0) | DU16: =ROUNDDOWN(#REF!,0) | DV16: =ROUNDDOWN(#REF!,0) | DW16: =ROUNDDOWN(#REF!,0) | DY16: =ROUNDDOWN(#REF!,0) | DZ16: =ROUNDDOWN(#REF!,0) | EA16: =ROUNDDOWN(#REF!,0) | EB16: =ROUNDDOWN(#REF!,0) | EC16: =ROUNDDOWN(#REF!,0)
A17: 7 | B17: 500000 | C17: 3 | D17: 3 | E17: 2 | F17: 2 | G17: 1 | H17: 1 | I17: 1 | L17: 7 | M17: =M$10*V16 | N17: 100000000 | O17: =(O$10*$V16) | P17: =(P$10*$V16) | Q17: =(Q$10*$V16) | R17: =(R$10*$V16) | S17: =(S$10*$V16) | T17: =(T$10*$V16) | U17: =(U$10*$V16) | V17: 8 | W17: =$W$9/V16 | X17: =SUM($M16/3,($N16*$M$4)/1000,($O16*$N$4)/1000,($P16*$O$4)/1000,($Q16*$P$4)/1000,($R16*$Q$4)/1000,($S16*$R$4)/1000,($T16*$S$4)/1000,($U16*$T$4)/1000) | Y17: =X16*5
A18: 8 | B18: 700000 | C18: 4 | D18: 4 | E18: 2 | F18: 2 | G18: 2 | H18: 1 | I18: 1 | L18: 8 | M18: =M$10*V17 | N18: 100000000 | O18: =(O$10*$V17) | P18: =(P$10*$V17) | Q18: =(Q$10*$V17) | R18: =(R$10*$V17) | S18: =(S$10*$V17) | T18: =(T$10*$V17) | U18: =(U$10*$V17) | V18: 10 | W18: =$W$9/V17 | X18: =SUM($M17/3,($N17*$M$4)/1000,($O17*$N$4)/1000,($P17*$O$4)/1000,($Q17*$P$4)/1000,($R17*$Q$4)/1000,($S17*$R$4)/1000,($T17*$S$4)/1000,($U17*$T$4)/1000) | Y18: =X17*5 | AA18: Bet Range 1
A19: 9 | B19: 1000000 | C19: 4 | D19: 4 | E19: 3 | F19: 3 | G19: 2 | H19: 2 | I19: 2 | Z19: =SUM(AA19:AE23,AG19:AK23,AM19:AQ23,AS19:AW23,AA26:AE30,AG26:AK30,AM26:AQ30,AS26:AW30)-SUM(AC21,AI21,AO21,AU21,AC28,AI28,AO28,AU28) | AA19: Level1 | AG19: Level2 | AM19: Level3 | AS19: Level4
A20: 10 | B20: 5000000 | C20: 5 | D20: 5 | E20: 4 | F20: 4 | G20: 3 | H20: 3 | I20: 3 | L20: Grand | M20: =N10 | N20: =M19/M$27 | O20: =1/N19 | P20: =O19/O$27 | Q20: =ROUND(P19*10000,0) | R20: =Q19/10 | S20: 1 | AA20: =M67 | AB20: =AA19 | AC20: =AB19 | AD20: =AC19 | AE20: =AD19 | AG20: =M68 | AH20: =AG19 | AI20: =AH19 | AJ20: =AI19 | AK20: =AJ19 | AM20: =M69 | AN20: =AM19 | AO20: =AN19 | AP20: =AO19 | AQ20: =AP19 | AS20: =M70 | AT20: =AS19 | AU20: =AT19 | AV20: =AU19 | AW20: =AV19
A21: 11 | B21: 10000000 | C21: 5 | D21: 5 | E21: 5 | F21: 5 | G21: 4 | H21: 4 | I21: 4 | L21: Mega | M21: =O10 | N21: =M20/M$27 | O21: =1/N20 | P21: =O20/O$27 | Q21: =ROUND(P20*10000,0) | R21: =Q20/10 | S21: =R20 | AA21: =AA19 | AB21: =AA20 | AC21: =AB20 | AD21: =AC20 | AE21: =AD20 | AG21: =AG19 | AH21: =AG20 | AI21: =AH20 | AJ21: =AI20 | AK21: =AJ20 | AM21: =AM19 | AN21: =AM20 | AO21: =AN20 | AP21: =AO20 | AQ21: =AP20 | AS21: =AS19 | AT21: =AS20 | AU21: =AT20 | AV21: =AU20 | AW21: =AV20
A22: 12 | B22: 50000000 | C22: 5 | D22: 5 | E22: 5 | F22: 5 | G22: 5 | H22: 5 | I22: 5 | L22: Major | M22: =P10 | N22: =M21/M$27 | O22: =1/N21 | P22: =O21/O$27 | Q22: =ROUND(P21*10000,0) | R22: =Q21/10 | S22: =R21 | AA22: =AA19 | AB22: =AA21 | AC22: =AB21 | AD22: =AC21 | AE22: =AD21 | AG22: =AG19 | AH22: =AG21 | AI22: =AH21 | AJ22: =AI21 | AK22: =AJ21 | AM22: =AM19 | AN22: =AM21 | AO22: =AN21 | AP22: =AO21 | AQ22: =AP21 | AS22: =AS19 | AT22: =AS21 | AU22: =AT21 | AV22: =AU21 | AW22: =AV21
L23: Minor | M23: =Q10 | N23: =M22/M$27 | O23: =1/N22 | P23: =O22/O$27 | Q23: =ROUND(P22*10000,0) | R23: =Q22/10 | S23: =R22 | AA23: =AA19 | AB23: =AA22 | AC23: =AB22 | AD23: =AC22 | AE23: =AD22 | AG23: =AG19 | AH23: =AG22 | AI23: =AH22 | AJ23: =AI22 | AK23: =AJ22 | AM23: =AM19 | AN23: =AM22 | AO23: =AN22 | AP23: =AO22 | AQ23: =AP22 | AS23: =AS19 | AT23: =AS22 | AU23: =AT22 | AV23: =AU22 | AW23: =AV22
L24: Mini | M24: =R10 | N24: =M23/M$27 | O24: =1/N23 | P24: =O23/O$27 | Q24: =ROUND(P23*10000,0) | R24: =Q23/10 | S24: =R23 | AA24: =AA19 | AB24: =AA23 | AC24: =AB23 | AD24: =AC23 | AE24: =AD23 | AG24: =AG19 | AH24: =AG23 | AI24: =AH23 | AJ24: =AI23 | AK24: =AJ23 | AM24: =AM19 | AN24: =AM23 | AO24: =AN23 | AP24: =AO23 | AQ24: =AP23 | AS24: =AS19 | AT24: =AS23 | AU24: =AT23 | AV24: =AU23 | AW24: =AV23
L25: Coin1 | M25: =S10 | N25: =M24/M$27 | O25: =1/N24 | P25: =O24/O$27 | Q25: =ROUND(P24*10000,0) | R25: =Q24/10 | S25: =1000-SUM(S19:S23, S25:S26)
B26: Class | C26: 1 | D26: 2 | E26: 3 | F26: 4 | G26: 5 | H26: 6 | I26: 7 | L26: Coin2 | M26: =T10 | N26: =M25/M$27 | O26: =1/N25 | P26: =O25/O$27 | Q26: =ROUND(P25*10000,0) | R26: =Q25/10 | S26: =R25 | AA26: Level5 | AG26: Level6 | AM26: Level7 | AS26: Level8
B27: Bet | C27: =C5 | D27: =D5 | E27: =E5 | F27: =F5 | G27: =G5 | H27: =H5 | I27: =I5 | L27: Coin3 | M27: =U10 | N27: =M26/M$27 | O27: =1/N26 | P27: =O26/O$27 | Q27: =ROUND(P26*10000,0) | R27: =Q26/10 | S27: =R26 | AA27: =M71 | AB27: =AA26 | AC27: =AB26 | AD27: =AC26 | AE27: =AD26 | AG27: =M72 | AH27: =AG26 | AI27: =AH26 | AJ27: =AI26 | AK27: =AJ26 | AM27: =M73 | AN27: =AM26 | AO27: =AN26 | AP27: =AO26 | AQ27: =AP26 | AS27: =M74 | AT27: =AS26 | AU27: =AT26 | AV27: =AU26 | AW27: =AV26
B28: Spins | C28: =C6 | D28: =D6 | E28: =E6 | F28: =F6 | G28: =G6 | H28: =H6 | I28: =I6 | M28: =SUM(M19:M26) | O28: =SUM(O19:O26) | Q28: =SUM(Q19:Q26) | R28: =Q27/10 | S28: =R27 | AA28: =AA26 | AB28: =AA27 | AC28: =AB27 | AD28: =AC27 | AE28: =AD27 | AG28: =AG26 | AH28: =AG27 | AI28: =AH27 | AJ28: =AI27 | AK28: =AJ27 | AM28: =AM26 | AN28: =AM27 | AO28: =AN27 | AP28: =AO27 | AQ28: =AP27 | AS28: =AS26 | AT28: =AS27 | AU28: =AT27 | AV28: =AU27 | AW28: =AV27
B29: Attendance Rate | C29: =C7 | D29: =D7 | E29: =E7 | F29: =F7 | G29: =G7 | H29: =H7 | I29: =I7 | AA29: =AA26 | AB29: =AA28 | AC29: =AB28 | AD29: =AC28 | AE29: =AD28 | AG29: =AG26 | AH29: =AG28 | AI29: =AH28 | AJ29: =AI28 | AK29: =AJ28 | AM29: =AM26 | AN29: =AM28 | AO29: =AN28 | AP29: =AO28 | AQ29: =AP28 | AS29: =AS26 | AT29: =AS28 | AU29: =AT28 | AV29: =AU28 | AW29: =AV28
B30: 16 | C30: =$B$29*C28 | D30: =$B$29*D28 | E30: =$B$29*E28 | F30: =$B$29*F28 | G30: =$B$29*G28 | H30: =$B$29*H28 | I30: =$B$29*I28 | AA30: =AA26 | AB30: =AA29 | AC30: =AB29 | AD30: =AC29 | AE30: =AD29 | AG30: =AG26 | AH30: =AG29 | AI30: =AH29 | AJ30: =AI29 | AK30: =AJ29 | AM30: =AM26 | AN30: =AM29 | AO30: =AN29 | AP30: =AO29 | AQ30: =AP29 | AS30: =AS26 | AT30: =AS29 | AU30: =AT29 | AV30: =AU29 | AW30: =AV29
B31: Total Spins | C31: =C27*C29 | D31: =D27*D29 | E31: =E27*E29 | F31: =F27*F29 | G31: =G27*G29 | H31: =H27*H29 | I31: =I27*I29 | M31: 10000 | N31: 22000 | O31: 25000 | P31: 22000 | Q31: 22000 | R31: <-Bet Range by Bingo Stage Coin Appearance Probability Setting | AA31: =AA26 | AB31: =AA30 | AC31: =AB30 | AD31: =AC30 | AE31: =AD30 | AG31: =AG26 | AH31: =AG30 | AI31: =AH30 | AJ31: =AI30 | AK31: =AJ30 | AM31: =AM26 | AN31: =AM30 | AO31: =AN30 | AP31: =AO30 | AQ31: =AP30 | AS31: =AS26 | AT31: =AS30 | AU31: =AT30 | AV31: =AU30 | AW31: =AV30
L32: Target Weight | M32: 2900 | N32: 1900 | O32: 900 | P32: 720 | Q32: 650 | R32: <-Bet Range by Bingo Stage Coin Appearance Probability Setting
M33: Bet 1 | N33: Bet 2 | O33: Bet 3 | P33: Bet 4 | Q33: Bet 5 | R33: Multi | AA33: Bet Range 2
L34: Level1 | M34: =$M$30/$R33 | N34: =$N$31/$R33 | O34: =$O$31/$R33 | P34: =$P$31/$R33 | Q34: =$Q$31/$R33 | R34: 1 | S34: <-Bingo Stage by Multi plier Setting | Z34: =SUM(AA34:AE38,AG34:AK38,AM34:AQ38,AS34:AW38,AA41:AE45,AG41:AK45,AM41:AQ45,AS41:AW45)-SUM(AC36,AI36,AO36,AU36,AC43,AI43,AO43,AU43) | AA34: Level1 | AG34: Level2 | AM34: Level3 | AS34: Level4
L35: Level2 | M35: =$M$30/$R34 | N35: =$N$30/$R34 | O35: =$O$31/$R34 | P35: =$P$31/$R34 | Q35: =$Q$31/$R34 | R35: 2 | AA35: =N67 | AB35: =AA34 | AC35: =AB34 | AD35: =AC34 | AE35: =AD34 | AG35: =N68 | AH35: =AG34 | AI35: =AH34 | AJ35: =AI34 | AK35: =AJ34 | AM35: =N69 | AN35: =AM34 | AO35: =AN34 | AP35: =AO34 | AQ35: =AP34 | AS35: =N70 | AT35: =AS34 | AU35: =AT34 | AV35: =AU34 | AW35: =AV34
L36: Level3 | M36: =$M$30/$R35 | N36: =$N$30/$R35 | O36: =$O$31/$R35 | P36: =$P$31/$R35 | Q36: =$Q$31/$R35 | R36: 3 | AA36: =AA34 | AB36: =AA35 | AC36: =AB35 | AD36: =AC35 | AE36: =AD35 | AG36: =AG34 | AH36: =AG35 | AI36: =AH35 | AJ36: =AI35 | AK36: =AJ35 | AM36: =AM34 | AN36: =AM35 | AO36: =AN35 | AP36: =AO35 | AQ36: =AP35 | AS36: =AS34 | AT36: =AS35 | AU36: =AT35 | AV36: =AU35 | AW36: =AV35
L37: Level4 | M37: =$M$31/$R36 | N37: =$N$30/$R36 | O37: =$O$30/$R36 | P37: =$P$31/$R36 | Q37: =$Q$31/$R36 | R37: 5 | AA37: =AA34 | AB37: =AA36 | AC37: =AB36 | AD37: =AC36 | AE37: =AD36 | AG37: =AG34 | AH37: =AG36 | AI37: =AH36 | AJ37: =AI36 | AK37: =AJ36 | AM37: =AM34 | AN37: =AM36 | AO37: =AN36 | AP37: =AO36 | AQ37: =AP36 | AS37: =AS34 | AT37: =AS36 | AU37: =AT36 | AV37: =AU36 | AW37: =AV36
L38: Level5 | M38: =$M$31/$R37 | N38: =$N$31/$R37 | O38: =$O$30/$R37 | P38: =$P$30/$R37 | Q38: =$Q$31/$R37 | R38: 6 | AA38: =AA34 | AB38: =AA37 | AC38: =AB37 | AD38: =AC37 | AE38: =AD37 | AG38: =AG34 | AH38: =AG37 | AI38: =AH37 | AJ38: =AI37 | AK38: =AJ37 | AM38: =AM34 | AN38: =AM37 | AO38: =AN37 | AP38: =AO37 | AQ38: =AP37 | AS38: =AS34 | AT38: =AS37 | AU38: =AT37 | AV38: =AU37 | AW38: =AV37
L39: Level6 | M39: =$M$31/$R38 | N39: =$N$31/$R38 | O39: =$O$30/$R38 | P39: =$P$30/$R38 | Q39: =$Q$30/$R38 | R39: 7 | AA39: =AA34 | AB39: =AA38 | AC39: =AB38 | AD39: =AC38 | AE39: =AD38 | AG39: =AG34 | AH39: =AG38 | AI39: =AH38 | AJ39: =AI38 | AK39: =AJ38 | AM39: =AM34 | AN39: =AM38 | AO39: =AN38 | AP39: =AO38 | AQ39: =AP38 | AS39: =AS34 | AT39: =AS38 | AU39: =AT38 | AV39: =AU38 | AW39: =AV38
L40: Level7 | M40: =$M$31/$R39 | N40: =$N$31/$R39 | O40: =$O$31/$R39 | P40: =$P$30/$R39 | Q40: =$Q$30/$R39 | R40: 8
...

Sheet Simulator
A1: CONFIDENTIAL — Shared for portfolio review purposes only. All game content is the property of its respective studio.
A2: Simul.html
A3: Default Diamond Amount
A4: =CONCATENATE(B3,C3,D3,E3,F3,G3,H3,I3,J3,K3,L3,M3,N3,O3,P3,Q3,R3) | B4: var CENTER_SYMBOL = [ | C4: ='Control Panel'!M10 | D4: , | E4: ='Control Panel'!M11 | F4: , | G4: ='Control Panel'!M12 | H4: , | I4: ='Control Panel'!M13 | J4: , | K4: ='Control Panel'!M14 | L4: , | M4: ='Control Panel'!M15 | N4: , | O4: ='Control Panel'!M16 | P4: , | Q4: ='Control Panel'!M17 | R4: ]; | S4: =A3
A6: Simul.js
A7: Jackpot Amount by Level
A8: =CONCATENATE(C7,D7,E7) | C8: var JACKPOT_GRAND = | D8: ='Control Panel'!N10 | E8: ; | S8: =A7
A10: var JACKPOT_VALUE = | S10: =A9
A11: =CONCATENATE(C10,D10,E10,F10,G10,H10,I10,J10,K10,L10,M10) | C11: [ | D11: [ | E11: ='Control Panel'!R10 | F11: , | G11: ='Control Panel'!Q10 | H11: , | I11: ='Control Panel'!P10 | J11: , | K11: ='Control Panel'!O10 | L11: ] | M11: , | S11: =A10
A12: =CONCATENATE(C11,D11,E11,F11,G11,H11,I11,J11,K11,L11,M11) | D12: [ | E12: ='Control Panel'!R11 | F12: , | G12: ='Control Panel'!Q11 | H12: , | I12: ='Control Panel'!P11 | J12: , | K12: ='Control Panel'!O11 | L12: ] | M12: , | S12: =A11
A13: =CONCATENATE(C12,D12,E12,F12,G12,H12,I12,J12,K12,L12,M12) | D13: [ | E13: ='Control Panel'!R12 | F13: , | G13: ='Control Panel'!Q12 | H13: , | I13: ='Control Panel'!P12 | J13: , | K13: ='Control Panel'!O12 | L13: ] | M13: , | S13: =A12
A14: =CONCATENATE(C13,D13,E13,F13,G13,H13,I13,J13,K13,L13,M13) | D14: [ | E14: ='Control Panel'!R13 | F14: , | G14: ='Control Panel'!Q13 | H14: , | I14: ='Control Panel'!P13 | J14: , | K14: ='Control Panel'!O13 | L14: ] | M14: , | S14: =A13
A15: =CONCATENATE(C14,D14,E14,F14,G14,H14,I14,J14,K14,L14,M14) | D15: [ | E15: ='Control Panel'!R14 | F15: , | G15: ='Control Panel'!Q14 | H15: , | I15: ='Control Panel'!P14 | J15: , | K15: ='Control Panel'!O14 | L15: ] | M15: , | S15: =A14
A16: =CONCATENATE(C15,D15,E15,F15,G15,H15,I15,J15,K15,L15,M15) | D16: [ | E16: ='Control Panel'!R15 | F16: , | G16: ='Control Panel'!Q15 | H16: , | I16: ='Control Panel'!P15 | J16: , | K16: ='Control Panel'!O15 | L16: ] | M16: , | S16: =A15
A17: =CONCATENATE(C16,D16,E16,F16,G16,H16,I16,J16,K16,L16,M16) | D17: [ | E17: ='Control Panel'!R16 | F17: , | G17: ='Control Panel'!Q16 | H17: , | I17: ='Control Panel'!P16 | J17: , | K17: ='Control Panel'!O16 | L17: ] | M17: , | S17: =A16
A18: =CONCATENATE(C17,D17,E17,F17,G17,H17,I17,J17,K17,L17,M17) | D18: [ | E18: ='Control Panel'!R17 | F18: , | G18: ='Control Panel'!Q17 | H18: , | I18: ='Control Panel'!P17 | J18: , | K18: ='Control Panel'!O17 | L18: ] | M18: , | S18: =A17
A19: =CONCATENATE(C18,D18,E18,F18,G18,H18,I18,J18,K18,L18,M18) | C19: ]; | S19: =A18
A21: Win Probability by Class and Bet Amount
A22: var HitCheckTable_Max = 1000; | S22: =A21
A23: var HitCheckTable = []; | S23: =A22
A24: =CONCATENATE(B23) | B24: HitCheckTable[0] = | S24: =A23
A25: =CONCATENATE(B24) | B25: [ | S25: =A24
A26: =CONCATENATE(B25,C25,D25,E25) | B26: [0, | C26: =IF('Control Panel'!C10>0,'Control Panel'!C1,0) | D26: ] | E26: , | S26: =A25
A27: =CONCATENATE(B26,C26,D26,E26) | B27: [9999, | C27: =IF('Control Panel'!C11>0,'Control Panel'!C1,0) | D27: ] | E27: , | F27: 2500 | S27: =A26
A28: =CONCATENATE(B27,C27,D27,E27) | B28: [49999, | C28: =IF('Control Panel'!C12>0,'Control Panel'!C1,0) | D28: ] | E28: , | F28: 11 | S28: =A27
A29: =CONCATENATE(B28,C28,D28,E28) | B29: [99999, | C29: =IF('Control Panel'!C13>0,'Control Panel'!C1,0) | D29: ] | E29: , | F29: =F26/F27 | S29: =A28
A30: =CONCATENATE(B29,C29,D29,E29) | B30: [199999, | C30: =IF('Control Panel'!C14>0,'Control Panel'!C1,0) | D30: ] | E30: , | S30: =A29
A31: =CONCATENATE(B30,C30,D30,E30) | B31: [299999, | C31: =IF('Control Panel'!C15>0,'Control Panel'!C1,0) | D31: ] | E31: , | S31: =A30
A32: =CONCATENATE(B31,C31,D31,E31) | B32: [499999, | C32: =IF('Control Panel'!C16>0,'Control Panel'!C1,0) | D32: ] | E32: , | S32: =A31
A33: =CONCATENATE(B32,C32,D32,E32) | B33: [999999, | C33: =IF('Control Panel'!C17>0,'Control Panel'!C1,0) | D33: ] | E33: , | S33: =A32
A34: =CONCATENATE(B33,C33,D33,E33) | B34: [4999999, | C34: =IF('Control Panel'!C18>0,'Control Panel'!C1,0) | D34: ] | E34: , | H34: 8 | I34: =H37/H33 | S34: =A33
A35: =CONCATENATE(B34,C34,D34,E34) | B35: [9999999, | C35: =IF('Control Panel'!C19>0,'Control Panel'!C1,0) | D35: ] | E35: , | H35: 9 | I35: =H37/H34 | S35: =A34
A36: =CONCATENATE(B35,C35,D35,E35) | B36: [49999999, | C36: =IF('Control Panel'!C20>0,'Control Panel'!C1,0) | D36: ] | E36: , | H36: 10 | I36: =H37/H35 | S36: =A35
A37: =CONCATENATE(B36,C36,D36,E36) | B37: [99999999, | C37: =IF('Control Panel'!C21>0,'Control Panel'!C1,0) | D37: ] | E37: , | H37: 11 | I37: =H37/H36 | S37: =A36
A38: =CONCATENATE(B37,C37,D37,E37) | B38: ]; | H38: =H33*H34*H35*H36 | S38: =A37
A39: =CONCATENATE(B38,C38,D38,E38) | S39: =A38
A40: =CONCATENATE(B39,C39,D39,E39) | B40: HitCheckTable[1] = | S40: =A39
A41: =CONCATENATE(B40,C40,D40,E40) | B41: [ | S41: =A40
A42: =CONCATENATE(B41,C41,D41,E41) | B42: [0, | C42: =IF('Control Panel'!D10>0,'Control Panel'!C1,0) | D42: ] | E42: , | S42: =A41
A43: =CONCATENATE(B42,C42,D42,E42) | B43: [9999, | C43: =IF('Control Panel'!D11>0,'Control Panel'!C1,0) | D43: ] | E43: , | S43: =A42
...

Sheet Diamond Exchange
A1: CONFIDENTIAL — Shared for portfolio review purposes only. All game content is the property of its respective studio.
A2: Based on 3000 Spins | F2: Exchange | H2: Range | N2: Bingo Position Expected Value
A3: Bingo Level | B3: Avg Bingo Prize | C3: Amount per Symbol | D3: Multiplier | F3: Diamond | G3: Earned Amount/Diamond | H3: 50 | I3: 100 | J3: 200 | K3: 500 | L3: 1000 | N3: Bingo Level | O3: 1 | P3: 2 | Q3: 3 | R3: 4 | S3: 5
A4: 1 | B4: 435515.22 | C4: 33501.171 | D4: 1 | F4: 20 | G4: =B3/F3 | H4: =$G3*H$2 | I4: =$G3*I$2 | J4: =$G3*J$2 | K4: =$G3*K$2 | L4: =$G3*L$2 | N4: 1 | O4: 611 | P4: 94 | Q4: 76 | R4: 81 | S4: 85
A5: 2 | B5: 871030.45 | C5: 67002.342 | D5: 2 | F5: 40 | G5: =B4/F4 | H5: =$G4*H$2 | I5: =$G4*I$2 | J5: =$G4*J$2 | K5: =$G4*K$2 | L5: =$G4*L$2 | N5: 2 | O5: 305 | P5: 536 | Q5: 39 | R5: 41 | S5: 43
A6: 3 | B6: 1306545.7 | C6: 100503.51 | D6: 3 | F6: 60 | G6: =B5/F5 | H6: =$G5*H$2 | I6: =$G5*I$2 | J6: =$G5*J$2 | K6: =$G5*K$2 | L6: =$G5*L$2 | N6: 3 | O6: 204 | P6: 357 | Q6: 26 | R6: 27 | S6: 28
A7: 4 | B7: 2177576.1 | C7: 167505.86 | D7: 5 | F7: 100 | G7: =B6/F6 | H7: =$G6*H$2 | I7: =$G6*I$2 | J7: =$G6*J$2 | K7: =$G6*K$2 | L7: =$G6*L$2 | N7: 4 | O7: 35 | P7: 214 | Q7: 428 | R7: 16 | S7: 17
A8: 5 | B8: 2613091.3 | C8: 201007.03 | D8: 6 | F8: 120 | G8: =B7/F7 | H8: =$G7*H$2 | I8: =$G7*I$2 | J8: =$G7*J$2 | K8: =$G7*K$2 | L8: =$G7*L$2 | N8: 5 | O8: 30 | P8: 15 | Q8: 357 | R8: 413 | S8: 14
A9: 6 | B9: 3048606.6 | C9: 234508.2 | D9: 7 | F9: 140 | G9: =B8/F8 | H9: =$G8*H$2 | I9: =$G8*I$2 | J9: =$G8*J$2 | K9: =$G8*K$2 | L9: =$G8*L$2 | N9: 6 | O9: 25 | P9: 13 | Q9: 306 | R9: 354 | S9: 413
A10: 7 | B10: 3484121.8 | C10: 268009.37 | D10: 8 | F10: 160 | G10: =B9/F9 | H10: =$G9*H$2 | I10: =$G9*I$2 | J10: =$G9*J$2 | K10: =$G9*K$2 | L10: =$G9*L$2 | N10: 7 | O10: 22 | P10: 12 | Q10: 10 | R10: 310 | S10: 361
A11: 8 | B11: 4355152.2 | C11: 335011.71 | D11: 10 | F11: 200 | G11: =B10/F10 | H11: =$G10*H$2 | I11: =$G10*I$2 | J11: =$G10*J$2 | K11: =$G10*K$2 | L11: =$G10*L$2 | N11: 8 | O11: 18 | P11: 9 | Q11: 8 | R11: 8 | S11: 289
G12: Average | H12: =AVERAGE(H3:H10) | I12: =AVERAGE(I3:I10) | J12: =AVERAGE(J3:J10) | K12: =AVERAGE(K3:K10) | L12: =AVERAGE(L3:L10) | N12: Daily Expected Value | O12: 627316 | P12: 1006619 | Q12: 1830605.3 | R12: 2124709.6 | S12: 2448109.6
F13: Recommended-> | G13: 0.1 | H13: =H$11*$G12 | I13: =I$11*$G12 | J13: =J$11*$G12 | K13: =K$11*$G12 | L13: =L$11*$G12 | O13: Exchange Range
G14: 0.2 | H14: =H$11*$G13 | I14: =I$11*$G13 | J14: =J$11*$G13 | K14: =K$11*$G13 | L14: =L$11*$G13 | N14: Bingo Level | O14: 50 | P14: 100 | Q14: 200 | R14: 500 | S14: 1000 | T14: Bingo Prize
G15: 0.3 | H15: =H$11*$G14 | I15: =I$11*$G14 | J15: =J$11*$G14 | K15: =K$11*$G14 | L15: =L$11*$G14 | N15: 1 | O15: 0.5 | T15: 435515.22
N16: 2 | O16: 0.5 | P16: 0.5 | T16: 871030.45
N17: 3 | O17: 0.5 | P17: 0.5 | Q17: 1 | T17: 1306545.7
N18: 4 | O18: 0.5 | P18: 0.5 | Q18: 1 | R18: 1 | T18: 2177576.1
G19: Range | H19: 50 | I19: 100 | J19: 200 | K19: 500 | L19: 1000 | N19: 5 | P19: 0.5 | Q19: 0.5 | R19: 1 | S19: 1.5 | T19: 2613091.3
F20: Base Reward | G20: 0.1 | H20: =INDEX(H12:H14,MATCH($G19,$G$12:$G$14,0)) | I20: =INDEX(I12:I14,MATCH($G19,$G$12:$G$14,0)) | J20: =INDEX(J12:J14,MATCH($G19,$G$12:$G$14,0)) | K20: =INDEX(K12:K14,MATCH($G19,$G$12:$G$14,0)) | L20: =INDEX(L12:L14,MATCH($G19,$G$12:$G$14,0)) | N20: 6 | Q20: 0.5 | R20: 1 | S20: 1.5 | T20: 3048606.6
F21: Provided Bingo Coin | H21: =O31 | I21: =P31 | J21: =Q31 | K21: =R31 | L21: =S31 | N21: 7 | R21: 0.5 | S21: 1.5 | T21: 3484121.8
F22: Base Reward + Provided Bingo Coin | H22: =SUM(H19:H20) | I22: =SUM(I19:I20) | J22: =SUM(J19:J20) | K22: =SUM(K19:K20) | L22: =SUM(L19:L20) | N22: 8 | S22: 1.5 | T22: 4355152.2
F23: Bonus Rate | H23: =H21/H3 | I23: =I21/I3 | J23: =J21/J3 | K23: =K21/K3 | L23: =L21/L3 | N23: Provided Count | O23: =SUM(O14:O21) | P23: =SUM(P14:P21) | Q23: =SUM(Q14:Q21) | R23: =SUM(R14:R21) | S23: =SUM(S14:S21)
F24: Actual Diamond Value | G24: =AVERAGE(H22:L22) | H24: =G10*G23 | N24: 1 | O24: =$C3*O14 | P24: =$C3*P14 | Q24: =$C3*Q14 | R24: =$C3*R14 | S24: =$C3*S14
N25: 2 | O25: =$C4*O15 | P25: =$C4*P15 | Q25: =$C4*Q15 | R25: =$C4*R15 | S25: =$C4*S15
N26: 3 | O26: =$C5*O16 | P26: =$C5*P16 | Q26: =$C5*Q16 | R26: =$C5*R16 | S26: =$C5*S16
N27: 4 | O27: =$C6*O17 | P27: =$C6*P17 | Q27: =$C6*Q17 | R27: =$C6*R17 | S27: =$C6*S17
N28: 5 | O28: =$C7*O18 | P28: =$C7*P18 | Q28: =$C7*Q18 | R28: =$C7*R18 | S28: =$C7*S18
N29: 6 | O29: =$C8*O19 | P29: =$C8*P19 | Q29: =$C8*Q19 | R29: =$C8*R19 | S29: =$C8*S19
N30: 7 | O30: =$C9*O20 | P30: =$C9*P20 | Q30: =$C9*Q20 | R30: =$C9*R20 | S30: =$C9*S20
N31: 8 | O31: =$C10*O21 | P31: =$C10*P21 | Q31: =$C10*Q21 | R31: =$C10*R21 | S31: =$C10*S21
N32: Expected Value | O32: =SUM(O23:O30) | P32: =SUM(P23:P30) | Q32: =SUM(Q23:Q30) | R32: =SUM(R23:R30) | S32: =SUM(S23:S30)
N33: Multi | O33: 1 | P33: 2 | Q33: 4 | R33: 10 | S33: 20
P34: =$O$31*P32 | Q34: =$O$31*Q32 | R34: =$O$31*R32 | S34: =$O$31*S32

Sheet Live Server
A1: CONFIDENTIAL — Shared for portfolio review purposes only. All game content is the property of its respective studio.
A2: #Bet Range by Position Assignment. | B2: =CONCATENATE(C1,D1,E1,F1,G1,H1,I1,J1,K1,L1,M1,N1,O1,P1,Q1,R1,S1,T1,U1,V1,W1,X1,Y1,Z1,AA1,AB1,AC1,AD1,AE1,AF1,AG1,AH1,AI1,AJ1,AK1,AL1,AM1,AN1,AO1,AP1,AQ1,AR1,AS1,AT1,AU1,AV1,AW1,AX1,AY1,AZ1,BA1,BB1,BC1,BD1,BE1,BF1,BG1,BH1) | C2: #Bet Range by Position Assignment.
B3: =CONCATENATE(C2,D2,E2,F2,G2,H2,I2,J2,K2,L2,M2,N2,O2,P2,Q2,R2,S2,T2,U2,V2,W2,X2,Y2,Z2,AA2,AB2,AC2,AD2,AE2,AF2,AG2,AH2,AI2,AJ2,AK2,AL2,AM2,AN2,AO2,AP2,AQ2,AR2,AS2,AT2,AU2,AV2,AW2,AX2,AY2,AZ2,BA2,BB2,BC2,BD2,BE2,BF2,BG2,BH2) | C3: 0
A4: var eventBingoSelectTable = [ | B4: =CONCATENATE(C3,D3,E3,F3,G3,H3,I3,J3,K3,L3,M3,N3,O3,P3,Q3,R3,S3,T3,U3,V3,W3,X3,Y3,Z3,AA3,AB3,AC3,AD3,AE3,AF3,AG3,AH3,AI3,AJ3,AK3,AL3,AM3,AN3,AO3,AP3,AQ3,AR3,AS3,AT3,AU3,AV3,AW3,AX3,AY3,AZ3,BA3,BB3,BC3,BD3,BE3,BF3,BG3,BH3) | C4: var eventBingoSelectTable = [
A5: [ | B5: =CONCATENATE(C4,D4,E4,F4,G4,H4,I4,J4,K4,L4,M4,N4,O4,P4,Q4,R4,S4,T4,U4,V4,W4,X4,Y4,Z4,AA4,AB4,AC4,AD4,AE4,AF4,AG4,AH4,AI4,AJ4,AK4,AL4,AM4,AN4,AO4,AP4,AQ4,AR4,AS4,AT4,AU4,AV4,AW4,AX4,AY4,AZ4,BA4,BB4,BC4,BD4,BE4,BF4,BG4,BH4) | C5: [
A6: [1,5,1],[1,5,2],[1,5,3],[1,6,4],[1,5,5], | B6: =CONCATENATE(C5,D5,E5,F5,G5,H5,I5,J5,K5,L5,M5,N5,O5,P5,Q5,R5,S5,T5,U5,V5,W5,X5,Y5,Z5,AA5,AB5,AC5,AD5,AE5,AF5,AG5,AH5,AI5,AJ5,AK5,AL5,AM5,AN5,AO5,AP5,AQ5,AR5,AS5,AT5,AU5,AV5,AW5,AX5,AY5,AZ5,BA5,BB5,BC5,BD5,BE5,BF5,BG5,BH5) | C6: [1, | D6: ='Control Panel'!AA19 | E6: ,1],[1, | F6: ='Control Panel'!AB19 | G6: ,2],[1, | H6: ='Control Panel'!AD19 | I6: ,3],[1, | J6: ='Control Panel'!AD19 | K6: ,4],[1, | L6: ='Control Panel'!AE19 | M6: ,5],
A7: [1,5,6],[1,5,7],[1,5,8],[1,6,9],[1,5,10], | B7: =CONCATENATE(C6,D6,E6,F6,G6,H6,I6,J6,K6,L6,M6,N6,O6,P6,Q6,R6,S6,T6,U6,V6,W6,X6,Y6,Z6,AA6,AB6,AC6,AD6,AE6,AF6,AG6,AH6,AI6,AJ6,AK6,AL6,AM6,AN6,AO6,AP6,AQ6,AR6,AS6,AT6,AU6,AV6,AW6,AX6,AY6,AZ6,BA6,BB6,BC6,BD6,BE6,BF6,BG6,BH6) | C7: [1, | D7: ='Control Panel'!AA20 | E7: ,6],[1, | F7: ='Control Panel'!AB20 | G7: ,7],[1, | H7: ='Control Panel'!AD20 | I7: ,8],[1, | J7: ='Control Panel'!AD20 | K7: ,9],[1, | L7: ='Control Panel'!AE20 | M7: ,10],
A8: [1,5,11],[1,5,12],[1,0,13],[1,6,14],[1,5,15], | B8: =CONCATENATE(C7,D7,E7,F7,G7,H7,I7,J7,K7,L7,M7,N7,O7,P7,Q7,R7,S7,T7,U7,V7,W7,X7,Y7,Z7,AA7,AB7,AC7,AD7,AE7,AF7,AG7,AH7,AI7,AJ7,AK7,AL7,AM7,AN7,AO7,AP7,AQ7,AR7,AS7,AT7,AU7,AV7,AW7,AX7,AY7,AZ7,BA7,BB7,BC7,BD7,BE7,BF7,BG7,BH7) | C8: [1, | D8: ='Control Panel'!AA21 | E8: ,11],[1, | F8: ='Control Panel'!AB21 | G8: ,12],[1, | H8: 0 | I8: ,13],[1, | J8: ='Control Panel'!AD21 | K8: ,14],[1, | L8: ='Control Panel'!AE21 | M8: ,15],
A9: [1,5,16],[1,5,17],[1,5,18],[1,6,19],[1,5,20], | B9: =CONCATENATE(C8,D8,E8,F8,G8,H8,I8,J8,K8,L8,M8,N8,O8,P8,Q8,R8,S8,T8,U8,V8,W8,X8,Y8,Z8,AA8,AB8,AC8,AD8,AE8,AF8,AG8,AH8,AI8,AJ8,AK8,AL8,AM8,AN8,AO8,AP8,AQ8,AR8,AS8,AT8,AU8,AV8,AW8,AX8,AY8,AZ8,BA8,BB8,BC8,BD8,BE8,BF8,BG8,BH8) | C9: [1, | D9: ='Control Panel'!AA22 | E9: ,16],[1, | F9: ='Control Panel'!AB22 | G9: ,17],[1, | H9: ='Control Panel'!AD22 | I9: ,18],[1, | J9: ='Control Panel'!AD22 | K9: ,19],[1, | L9: ='Control Panel'!AE22 | M9: ,20],
A10: [1,5,21],[1,5,22],[1,5,23],[1,6,24],[1,5,25], | B10: =CONCATENATE(C9,D9,E9,F9,G9,H9,I9,J9,K9,L9,M9,N9,O9,P9,Q9,R9,S9,T9,U9,V9,W9,X9,Y9,Z9,AA9,AB9,AC9,AD9,AE9,AF9,AG9,AH9,AI9,AJ9,AK9,AL9,AM9,AN9,AO9,AP9,AQ9,AR9,AS9,AT9,AU9,AV9,AW9,AX9,AY9,AZ9,BA9,BB9,BC9,BD9,BE9,BF9,BG9,BH9) | C10: [1, | D10: ='Control Panel'!AA23 | E10: ,21],[1, | F10: ='Control Panel'!AB23 | G10: ,22],[1, | H10: ='Control Panel'!AD23 | I10: ,23],[1, | J10: ='Control Panel'!AD23 | K10: ,24],[1, | L10: ='Control Panel'!AE23 | M10: ,25],
B11: =CONCATENATE(C10,D10,E10,F10,G10,H10,I10,J10,K10,L10,M10,N10,O10,P10,Q10,R10,S10,T10,U10,V10,W10,X10,Y10,Z10,AA10,AB10,AC10,AD10,AE10,AF10,AG10,AH10,AI10,AJ10,AK10,AL10,AM10,AN10,AO10,AP10,AQ10,AR10,AS10,AT10,AU10,AV10,AW10,AX10,AY10,AZ10,BA10,BB10,BC10,BD10,BE10,BF10,BG10,BH10)
A12: [2,5,1],[2,5,2],[2,5,3],[2,6,4],[2,5,5], | B12: =CONCATENATE(C11,D11,E11,F11,G11,H11,I11,J11,K11,L11,M11,N11,O11,P11,Q11,R11,S11,T11,U11,V11,W11,X11,Y11,Z11,AA11,AB11,AC11,AD11,AE11,AF11,AG11,AH11,AI11,AJ11,AK11,AL11,AM11,AN11,AO11,AP11,AQ11,AR11,AS11,AT11,AU11,AV11,AW11,AX11,AY11,AZ11,BA11,BB11,BC11,BD11,BE11,BF11,BG11,BH11) | C12: [2, | D12: ='Control Panel'!AG19 | E12: ,1],[2, | F12: =$D$11 | G12: ,2],[2, | H12: =$D$11 | I12: ,3],[2, | J12: =$D$11 | K12: ,4],[2, | L12: =$D$11 | M12: ,5],
A13: [2,5,6],[2,5,7],[2,5,8],[2,6,9],[2,5,10], | B13: =CONCATENATE(C12,D12,E12,F12,G12,H12,I12,J12,K12,L12,M12,N12,O12,P12,Q12,R12,S12,T12,U12,V12,W12,X12,Y12,Z12,AA12,AB12,AC12,AD12,AE12,AF12,AG12,AH12,AI12,AJ12,AK12,AL12,AM12,AN12,AO12,AP12,AQ12,AR12,AS12,AT12,AU12,AV12,AW12,AX12,AY12,AZ12,BA12,BB12,BC12,BD12,BE12,BF12,BG12,BH12) | C13: [2, | D13: =$D$11 | E13: ,6],[2, | F13: =$D$11 | G13: ,7],[2, | H13: =$D$11 | I13: ,8],[2, | J13: =$D$11 | K13: ,9],[2, | L13: =$D$11 | M13: ,10],
A14: [2,5,11],[2,5,12],[2,0,13],[2,6,14],[2,5,15], | B14: =CONCATENATE(C13,D13,E13,F13,G13,H13,I13,J13,K13,L13,M13,N13,O13,P13,Q13,R13,S13,T13,U13,V13,W13,X13,Y13,Z13,AA13,AB13,AC13,AD13,AE13,AF13,AG13,AH13,AI13,AJ13,AK13,AL13,AM13,AN13,AO13,AP13,AQ13,AR13,AS13,AT13,AU13,AV13,AW13,AX13,AY13,AZ13,BA13,BB13,BC13,BD13,BE13,BF13,BG13,BH13) | C14: [2, | D14: =$D$11 | E14: ,11],[2, | F14: =$D$11 | G14: ,12],[2, | H14: 0 | I14: ,13],[2, | J14: =$D$11 | K14: ,14],[2, | L14: =$D$11 | M14: ,15],
A15: [2,5,16],[2,5,17],[2,5,18],[2,6,19],[2,5,20], | B15: =CONCATENATE(C14,D14,E14,F14,G14,H14,I14,J14,K14,L14,M14,N14,O14,P14,Q14,R14,S14,T14,U14,V14,W14,X14,Y14,Z14,AA14,AB14,AC14,AD14,AE14,AF14,AG14,AH14,AI14,AJ14,AK14,AL14,AM14,AN14,AO14,AP14,AQ14,AR14,AS14,AT14,AU14,AV14,AW14,AX14,AY14,AZ14,BA14,BB14,BC14,BD14,BE14,BF14,BG14,BH14) | C15: [2, | D15: =$D$11 | E15: ,16],[2, | F15: =$D$11 | G15: ,17],[2, | H15: =$D$11 | I15: ,18],[2, | J15: =$D$11 | K15: ,19],[2, | L15: =$D$11 | M15: ,20],
A16: [2,5,21],[2,5,22],[2,5,23],[2,6,24],[2,5,25], | B16: =CONCATENATE(C15,D15,E15,F15,G15,H15,I15,J15,K15,L15,M15,N15,O15,P15,Q15,R15,S15,T15,U15,V15,W15,X15,Y15,Z15,AA15,AB15,AC15,AD15,AE15,AF15,AG15,AH15,AI15,AJ15,AK15,AL15,AM15,AN15,AO15,AP15,AQ15,AR15,AS15,AT15,AU15,AV15,AW15,AX15,AY15,AZ15,BA15,BB15,BC15,BD15,BE15,BF15,BG15,BH15) | C16: [2, | D16: =$D$11 | E16: ,21],[2, | F16: =$D$11 | G16: ,22],[2, | H16: =$D$11 | I16: ,23],[2, | J16: =$D$11 | K16: ,24],[2, | L16: =$D$11 | M16: ,25],
B17: =CONCATENATE(C16,D16,E16,F16,G16,H16,I16,J16,K16,L16,M16,N16,O16,P16,Q16,R16,S16,T16,U16,V16,W16,X16,Y16,Z16,AA16,AB16,AC16,AD16,AE16,AF16,AG16,AH16,AI16,AJ16,AK16,AL16,AM16,AN16,AO16,AP16,AQ16,AR16,AS16,AT16,AU16,AV16,AW16,AX16,AY16,AZ16,BA16,BB16,BC16,BD16,BE16,BF16,BG16,BH16)
A18: [3,5,1],[3,5,2],[3,5,3],[3,6,4],[3,5,5], | B18: =CONCATENATE(C17,D17,E17,F17,G17,H17,I17,J17,K17,L17,M17,N17,O17,P17,Q17,R17,S17,T17,U17,V17,W17,X17,Y17,Z17,AA17,AB17,AC17,AD17,AE17,AF17,AG17,AH17,AI17,AJ17,AK17,AL17,AM17,AN17,AO17,AP17,AQ17,AR17,AS17,AT17,AU17,AV17,AW17,AX17,AY17,AZ17,BA17,BB17,BC17,BD17,BE17,BF17,BG17,BH17) | C18: [3, | D18: ='Control Panel'!AM19 | E18: ,1],[3, | F18: =$D$17 | G18: ,2],[3, | H18: =$D$17 | I18: ,3],[3, | J18: =$D$17 | K18: ,4],[3, | L18: =$D$17 | M18: ,5],
A19: [3,5,6],[3,5,7],[3,5,8],[3,6,9],[3,5,10], | B19: =CONCATENATE(C18,D18,E18,F18,G18,H18,I18,J18,K18,L18,M18,N18,O18,P18,Q18,R18,S18,T18,U18,V18,W18,X18,Y18,Z18,AA18,AB18,AC18,AD18,AE18,AF18,AG18,AH18,AI18,AJ18,AK18,AL18,AM18,AN18,AO18,AP18,AQ18,AR18,AS18,AT18,AU18,AV18,AW18,AX18,AY18,AZ18,BA18,BB18,BC18,BD18,BE18,BF18,BG18,BH18) | C19: [3, | D19: =$D$17 | E19: ,6],[3, | F19: =$D$17 | G19: ,7],[3, | H19: =$D$17 | I19: ,8],[3, | J19: =$D$17 | K19: ,9],[3, | L19: =$D$17 | M19: ,10],
A20: [3,5,11],[3,5,12],[3,0,13],[3,6,14],[3,5,15], | B20: =CONCATENATE(C19,D19,E19,F19,G19,H19,I19,J19,K19,L19,M19,N19,O19,P19,Q19,R19,S19,T19,U19,V19,W19,X19,Y19,Z19,AA19,AB19,AC19,AD19,AE19,AF19,AG19,AH19,AI19,AJ19,AK19,AL19,AM19,AN19,AO19,AP19,AQ19,AR19,AS19,AT19,AU19,AV19,AW19,AX19,AY19,AZ19,BA19,BB19,BC19,BD19,BE19,BF19,BG19,BH19) | C20: [3, | D20: =$D$17 | E20: ,11],[3, | F20: =$D$17 | G20: ,12],[3, | H20: 0 | I20: ,13],[3, | J20: =$D$17 | K20: ,14],[3, | L20: =$D$17 | M20: ,15],
A21: [3,5,16],[3,5,17],[3,5,18],[3,6,19],[3,5,20], | B21: =CONCATENATE(C20,D20,E20,F20,G20,H20,I20,J20,K20,L20,M20,N20,O20,P20,Q20,R20,S20,T20,U20,V20,W20,X20,Y20,Z20,AA20,AB20,AC20,AD20,AE20,AF20,AG20,AH20,AI20,AJ20,AK20,AL20,AM20,AN20,AO20,AP20,AQ20,AR20,AS20,AT20,AU20,AV20,AW20,AX20,AY20,AZ20,BA20,BB20,BC20,BD20,BE20,BF20,BG20,BH20) | C21: [3, | D21: =$D$17 | E21: ,16],[3, | F21: =$D$17 | G21: ,17],[3, | H21: =$D$17 | I21: ,18],[3, | J21: =$D$17 | K21: ,19],[3, | L21: =$D$17 | M21: ,20],
A22: [3,5,21],[3,5,22],[3,5,23],[3,6,24],[3,5,25], | B22: =CONCATENATE(C21,D21,E21,F21,G21,H21,I21,J21,K21,L21,M21,N21,O21,P21,Q21,R21,S21,T21,U21,V21,W21,X21,Y21,Z21,AA21,AB21,AC21,AD21,AE21,AF21,AG21,AH21,AI21,AJ21,AK21,AL21,AM21,AN21,AO21,AP21,AQ21,AR21,AS21,AT21,AU21,AV21,AW21,AX21,AY21,AZ21,BA21,BB21,BC21,BD21,BE21,BF21,BG21,BH21) | C22: [3, | D22: =$D$17 | E22: ,21],[3, | F22: =$D$17 | G22: ,22],[3, | H22: =$D$17 | I22: ,23],[3, | J22: =$D$17 | K22: ,24],[3, | L22: =$D$17 | M22: ,25],
B23: =CONCATENATE(C22,D22,E22,F22,G22,H22,I22,J22,K22,L22,M22,N22,O22,P22,Q22,R22,S22,T22,U22,V22,W22,X22,Y22,Z22,AA22,AB22,AC22,AD22,AE22,AF22,AG22,AH22,AI22,AJ22,AK22,AL22,AM22,AN22,AO22,AP22,AQ22,AR22,AS22,AT22,AU22,AV22,AW22,AX22,AY22,AZ22,BA22,BB22,BC22,BD22,BE22,BF22,BG22,BH22)
A24: [4,5,1],[4,5,2],[4,5,3],[4,6,4],[4,5,5], | B24: =CONCATENATE(C23,D23,E23,F23,G23,H23,I23,J23,K23,L23,M23,N23,O23,P23,Q23,R23,S23,T23,U23,V23,W23,X23,Y23,Z23,AA23,AB23,AC23,AD23,AE23,AF23,AG23,AH23,AI23,AJ23,AK23,AL23,AM23,AN23,AO23,AP23,AQ23,AR23,AS23,AT23,AU23,AV23,AW23,AX23,AY23,AZ23,BA23,BB23,BC23,BD23,BE23,BF23,BG23,BH23) | C24: [4, | D24: ='Control Panel'!AS19 | E24: ,1],[4, | F24: =$D$23 | G24: ,2],[4, | H24: =$D$23 | I24: ,3],[4, | J24: =$D$23 | K24: ,4],[4, | L24: =$D$23 | M24: ,5],
A25: [4,5,6],[4,5,7],[4,5,8],[4,6,9],[4,5,10], | B25: =CONCATENATE(C24,D24,E24,F24,G24,H24,I24,J24,K24,L24,M24,N24,O24,P24,Q24,R24,S24,T24,U24,V24,W24,X24,Y24,Z24,AA24,AB24,AC24,AD24,AE24,AF24,AG24,AH24,AI24,AJ24,AK24,AL24,AM24,AN24,AO24,AP24,AQ24,AR24,AS24,AT24,AU24,AV24,AW24,AX24,AY24,AZ24,BA24,BB24,BC24,BD24,BE24,BF24,BG24,BH24) | C25: [4, | D25: =$D$23 | E25: ,6],[4, | F25: =$D$23 | G25: ,7],[4, | H25: =$D$23 | I25: ,8],[4, | J25: =$D$23 | K25: ,9],[4, | L25: =$D$23 | M25: ,10],
A26: [4,5,11],[4,5,12],[4,0,13],[4,6,14],[4,5,15], | B26: =CONCATENATE(C25,D25,E25,F25,G25,H25,I25,J25,K25,L25,M25,N25,O25,P25,Q25,R25,S25,T25,U25,V25,W25,X25,Y25,Z25,AA25,AB25,AC25,AD25,AE25,AF25,AG25,AH25,AI25,AJ25,AK25,AL25,AM25,AN25,AO25,AP25,AQ25,AR25,AS25,AT25,AU25,AV25,AW25,AX25,AY25,AZ25,BA25,BB25,BC25,BD25,BE25,BF25,BG25,BH25) | C26: [4, | D26: =$D$23 | E26: ,11],[4, | F26: =$D$23 | G26: ,12],[4, | H26: 0 | I26: ,13],[4, | J26: =$D$23 | K26: ,14],[4, | L26: =$D$23 | M26: ,15],
A27: [4,5,16],[4,5,17],[4,5,18],[4,6,19],[4,5,20], | B27: =CONCATENATE(C26,D26,E26,F26,G26,H26,I26,J26,K26,L26,M26,N26,O26,P26,Q26,R26,S26,T26,U26,V26,W26,X26,Y26,Z26,AA26,AB26,AC26,AD26,AE26,AF26,AG26,AH26,AI26,AJ26,AK26,AL26,AM26,AN26,AO26,AP26,AQ26,AR26,AS26,AT26,AU26,AV26,AW26,AX26,AY26,AZ26,BA26,BB26,BC26,BD26,BE26,BF26,BG26,BH26) | C27: [4, | D27: =$D$23 | E27: ,16],[4, | F27: =$D$23 | G27: ,17],[4, | H27: =$D$23 | I27: ,18],[4, | J27: =$D$23 | K27: ,19],[4, | L27: =$D$23 | M27: ,20],
A28: [4,5,21],[4,5,22],[4,5,23],[4,6,24],[4,5,25], | B28: =CONCATENATE(C27,D27,E27,F27,G27,H27,I27,J27,K27,L27,M27,N27,O27,P27,Q27,R27,S27,T27,U27,V27,W27,X27,Y27,Z27,AA27,AB27,AC27,AD27,AE27,AF27,AG27,AH27,AI27,AJ27,AK27,AL27,AM27,AN27,AO27,AP27,AQ27,AR27,AS27,AT27,AU27,AV27,AW27,AX27,AY27,AZ27,BA27,BB27,BC27,BD27,BE27,BF27,BG27,BH27) | C28: [4, | D28: =$D$23 | E28: ,21],[4, | F28: =$D$23 | G28: ,22],[4, | H28: =$D$23 | I28: ,23],[4, | J28: =$D$23 | K28: ,24],[4, | L28: =$D$23 | M28: ,25],
B29: =CONCATENATE(C28,D28,E28,F28,G28,H28,I28,J28,K28,L28,M28,N28,O28,P28,Q28,R28,S28,T28,U28,V28,W28,X28,Y28,Z28,AA28,AB28,AC28,AD28,AE28,AF28,AG28,AH28,AI28,AJ28,AK28,AL28,AM28,AN28,AO28,AP28,AQ28,AR28,AS28,AT28,AU28,AV28,AW28,AX28,AY28,AZ28,BA28,BB28,BC28,BD28,BE28,BF28,BG28,BH28)
A30: [5,5,1],[5,5,2],[5,5,3],[5,6,4],[5,5,5], | B30: =CONCATENATE(C29,D29,E29,F29,G29,H29,I29,J29,K29,L29,M29,N29,O29,P29,Q29,R29,S29,T29,U29,V29,W29,X29,Y29,Z29,AA29,AB29,AC29,AD29,AE29,AF29,AG29,AH29,AI29,AJ29,AK29,AL29,AM29,AN29,AO29,AP29,AQ29,AR29,AS29,AT29,AU29,AV29,AW29,AX29,AY29,AZ29,BA29,BB29,BC29,BD29,BE29,BF29,BG29,BH29) | C30: [5, | D30: ='Control Panel'!AA26 | E30: ,1],[5, | F30: =$D$29 | G30: ,2],[5, | H30: =$D$29 | I30: ,3],[5, | J30: =$D$29 | K30: ,4],[5, | L30: =$D$29 | M30: ,5],
A31: [5,5,6],[5,5,7],[5,5,8],[5,6,9],[5,5,10], | B31: =CONCATENATE(C30,D30,E30,F30,G30,H30,I30,J30,K30,L30,M30,N30,O30,P30,Q30,R30,S30,T30,U30,V30,W30,X30,Y30,Z30,AA30,AB30,AC30,AD30,AE30,AF30,AG30,AH30,AI30,AJ30,AK30,AL30,AM30,AN30,AO30,AP30,AQ30,AR30,AS30,AT30,AU30,AV30,AW30,AX30,AY30,AZ30,BA30,BB30,BC30,BD30,BE30,BF30,BG30,BH30) | C31: [5, | D31: =$D$29 | E31: ,6],[5, | F31: =$D$29 | G31: ,7],[5, | H31: =$D$29 | I31: ,8],[5, | J31: =$D$29 | K31: ,9],[5, | L31: =$D$29 | M31: ,10],
A32: [5,5,11],[5,5,12],[5,0,13],[5,6,14],[5,5,15], | B32: =CONCATENATE(C31,D31,E31,F31,G31,H31,I31,J31,K31,L31,M31,N31,O31,P31,Q31,R31,S31,T31,U31,V31,W31,X31,Y31,Z31,AA31,AB31,AC31,AD31,AE31,AF31,AG31,AH31,AI31,AJ31,AK31,AL31,AM31,AN31,AO31,AP31,AQ31,AR31,AS31,AT31,AU31,AV31,AW31,AX31,AY31,AZ31,BA31,BB31,BC31,BD31,BE31,BF31,BG31,BH31) | C32: [5, | D32: =$D$29 | E32: ,11],[5, | F32: =$D$29 | G32: ,12],[5, | H32: 0 | I32: ,13],[5, | J32: =$D$29 | K32: ,14],[5, | L32: =$D$29 | M32: ,15],
A33: [5,5,16],[5,5,17],[5,5,18],[5,6,19],[5,5,20], | B33: =CONCATENATE(C32,D32,E32,F32,G32,H32,I32,J32,K32,L32,M32,N32,O32,P32,Q32,R32,S32,T32,U32,V32,W32,X32,Y32,Z32,AA32,AB32,AC32,AD32,AE32,AF32,AG32,AH32,AI32,AJ32,AK32,AL32,AM32,AN32,AO32,AP32,AQ32,AR32,AS32,AT32,AU32,AV32,AW32,AX32,AY32,AZ32,BA32,BB32,BC32,BD32,BE32,BF32,BG32,BH32) | C33: [5, | D33: =$D$29 | E33: ,16],[5, | F33: =$D$29 | G33: ,17],[5, | H33: =$D$29 | I33: ,18],[5, | J33: =$D$29 | K33: ,19],[5, | L33: =$D$29 | M33: ,20],
A34: [5,5,21],[5,5,22],[5,5,23],[5,6,24],[5,5,25], | B34: =CONCATENATE(C33,D33,E33,F33,G33,H33,I33,J33,K33,L33,M33,N33,O33,P33,Q33,R33,S33,T33,U33,V33,W33,X33,Y33,Z33,AA33,AB33,AC33,AD33,AE33,AF33,AG33,AH33,AI33,AJ33,AK33,AL33,AM33,AN33,AO33,AP33,AQ33,AR33,AS33,AT33,AU33,AV33,AW33,AX33,AY33,AZ33,BA33,BB33,BC33,BD33,BE33,BF33,BG33,BH33) | C34: [5, | D34: =$D$29 | E34: ,21],[5, | F34: =$D$29 | G34: ,22],[5, | H34: =$D$29 | I34: ,23],[5, | J34: =$D$29 | K34: ,24],[5, | L34: =$D$29 | M34: ,25],
B35: =CONCATENATE(C34,D34,E34,F34,G34,H34,I34,J34,K34,L34,M34,N34,O34,P34,Q34,R34,S34,T34,U34,V34,W34,X34,Y34,Z34,AA34,AB34,AC34,AD34,AE34,AF34,AG34,AH34,AI34,AJ34,AK34,AL34,AM34,AN34,AO34,AP34,AQ34,AR34,AS34,AT34,AU34,AV34,AW34,AX34,AY34,AZ34,BA34,BB34,BC34,BD34,BE34,BF34,BG34,BH34)
A36: [6,5,1],[6,5,2],[6,5,3],[6,6,4],[6,5,5], | B36: =CONCATENATE(C35,D35,E35,F35,G35,H35,I35,J35,K35,L35,M35,N35,O35,P35,Q35,R35,S35,T35,U35,V35,W35,X35,Y35,Z35,AA35,AB35,AC35,AD35,AE35,AF35,AG35,AH35,AI35,AJ35,AK35,AL35,AM35,AN35,AO35,AP35,AQ35,AR35,AS35,AT35,AU35,AV35,AW35,AX35,AY35,AZ35,BA35,BB35,BC35,BD35,BE35,BF35,BG35,BH35) | C36: [6, | D36: ='Control Panel'!AG26 | E36: ,1],[6, | F36: =$D$35 | G36: ,2],[6, | H36: =$D$35 | I36: ,3],[6, | J36: =$D$35 | K36: ,4],[6, | L36: =$D$35 | M36: ,5],
A37: [6,5,6],[6,5,7],[6,5,8],[6,6,9],[6,5,10], | B37: =CONCATENATE(C36,D36,E36,F36,G36,H36,I36,J36,K36,L36,M36,N36,O36,P36,Q36,R36,S36,T36,U36,V36,W36,X36,Y36,Z36,AA36,AB36,AC36,AD36,AE36,AF36,AG36,AH36,AI36,AJ36,AK36,AL36,AM36,AN36,AO36,AP36,AQ36,AR36,AS36,AT36,AU36,AV36,AW36,AX36,AY36,AZ36,BA36,BB36,BC36,BD36,BE36,BF36,BG36,BH36) | C37: [6, | D37: =$D$35 | E37: ,6],[6, | F37: =$D$35 | G37: ,7],[6, | H37: =$D$35 | I37: ,8],[6, | J37: =$D$35 | K37: ,9],[6, | L37: =$D$35 | M37: ,10],
A38: [6,5,11],[6,5,12],[6,0,13],[6,6,14],[6,5,15], | B38: =CONCATENATE(C37,D37,E37,F37,G37,H37,I37,J37,K37,L37,M37,N37,O37,P37,Q37,R37,S37,T37,U37,V37,W37,X37,Y37,Z37,AA37,AB37,AC37,AD37,AE37,AF37,AG37,AH37,AI37,AJ37,AK37,AL37,AM37,AN37,AO37,AP37,AQ37,AR37,AS37,AT37,AU37,AV37,AW37,AX37,AY37,AZ37,BA37,BB37,BC37,BD37,BE37,BF37,BG37,BH37) | C38: [6, | D38: =$D$35 | E38: ,11],[6, | F38: =$D$35 | G38: ,12],[6, | H38: 0 | I38: ,13],[6, | J38: =$D$35 | K38: ,14],[6, | L38: =$D$35 | M38: ,15],
A39: [6,5,16],[6,5,17],[6,5,18],[6,6,19],[6,5,20], | B39: =CONCATENATE(C38,D38,E38,F38,G38,H38,I38,J38,K38,L38,M38,N38,O38,P38,Q38,R38,S38,T38,U38,V38,W38,X38,Y38,Z38,AA38,AB38,AC38,AD38,AE38,AF38,AG38,AH38,AI38,AJ38,AK38,AL38,AM38,AN38,AO38,AP38,AQ38,AR38,AS38,AT38,AU38,AV38,AW38,AX38,AY38,AZ38,BA38,BB38,BC38,BD38,BE38,BF38,BG38,BH38) | C39: [6, | D39: =$D$35 | E39: ,16],[6, | F39: =$D$35 | G39: ,17],[6, | H39: =$D$35 | I39: ,18],[6, | J39: =$D$35 | K39: ,19],[6, | L39: =$D$35 | M39: ,20],
A40: [6,5,21],[6,5,22],[6,5,23],[6,6,24],[6,5,25], | B40: =CONCATENATE(C39,D39,E39,F39,G39,H39,I39,J39,K39,L39,M39,N39,O39,P39,Q39,R39,S39,T39,U39,V39,W39,X39,Y39,Z39,AA39,AB39,AC39,AD39,AE39,AF39,AG39,AH39,AI39,AJ39,AK39,AL39,AM39,AN39,AO39,AP39,AQ39,AR39,AS39,AT39,AU39,AV39,AW39,AX39,AY39,AZ39,BA39,BB39,BC39,BD39,BE39,BF39,BG39,BH39) | C40: [6, | D40: =$D$35 | E40: ,21],[6, | F40: =$D$35 | G40: ,22],[6, | H40: =$D$35 | I40: ,23],[6, | J40: =$D$35 | K40: ,24],[6, | L40: =$D$35 | M40: ,25],
...

Sheet Bet5
A1: CONFIDENTIAL — Shared for portfolio review purposes only. All game content is the property of its respective studio.
A2: New | B2: Item | C2: Acquired | D2: : | E2: 210.00K | F2: (7, | G2: 8) | K2: Spins | L2: 3000
A3: New | B3: Item | C3: Acquired | D3: : | E3: 75.00K | F3: (6, | G3: 24) | K3: Symbol Pick | L3: =COUNTIF(A:A,"") | M3: =L1/L2
A4: New | B4: Item | C4: Acquired | D4: : | E4: Mini | F4: (8, | G4: 16) | K4: Bingo Wins | L4: =COUNTIF(A:A,"Line") | M4: =L1/L3
A5: New | B5: Item | C5: Acquired | D5: : | E5: 105.00K | F5: (4, | G5: 10) | L5: =L2/L3
A6: New | B6: Item | C6: Acquired | D6: : | E6: 125.00K | F6: (6, | G6: 7)
A7: New | B7: Item | C7: Acquired | D7: : | E7: 210.00K | F7: (7, | G7: 14)
A8: New | B8: Item | C8: Acquired | D8: : | E8: 90.00K | F8: (7, | G8: 23)
